<?xml version="1.0" ?>
<!-- =================================================================================== -->
<!-- |    This document was autogenerated by xacro from /home/cp/local_ws/demo_maker_faire_backup_ws/src/panda-softhand/panda_softhand_description/robot/urdf/panda_softhand.urdf.xacro | -->
<!-- |    EDITING THIS FILE BY HAND IS NOT RECOMMENDED                                 | -->
<!-- =================================================================================== -->
<robot name="panda_softhand">
    <material name="qbhand/optional">
        <color rgba="0.0 0.5 0.8 1.0" />
    </material>
    <material name="qbhand/base">
        <color rgba="0.35 0.35 0.35 1.0" />
    </material>
    <material name="qbhand/palm">
        <color rgba="0.35 0.35 0.35 1.0" />
    </material>
    <material name="qbhand/knuckle">
        <color rgba="0.35 0.35 0.35 1.0" />
    </material>
    <material name="qbhand/proximal">
        <color rgba="0.35 0.35 0.35 1.0" />
    </material>
    <material name="qbhand/middle">
        <color rgba="0.35 0.35 0.35 1.0" />
    </material>
    <material name="qbhand/distal">
        <color rgba="0.35 0.35 0.35 1.0" />
    </material>
    <material name="qbhand/default">
        <color rgba="0.35 0.35 0.35 1.0" />
    </material>
    <material name="Red">
        <color rgba="1.0 0 0 1.0" />
    </material>
    <material name="Cyan">
        <color rgba="0 1.0 1.0 1.0" />
    </material>
    <!-- WORLD -->
    <link name="world" />
    <link name="box_link">
        <visual>
            <geometry>
                <box size="0.75 0.75 0.94" />
            </geometry>
            <material name="Red" />
        </visual>
        <collision>
            <geometry>
                <box size="0.75 0.75 0.94" />
            </geometry>
        </collision>
        <inertial>
            <mass value="0.1" />
            <origin xyz="0 0 0" rpy="0 0 0" />
            <inertia ixx="0.03" iyy="0.03" izz="0.03" ixy="0.0" ixz="0.0" iyz="0.0" />
        </inertial>
    </link>
    <joint name="world_to_box_joint" type="fixed">
        <origin rpy="0.0 0.0 0.0" xyz="0.0 0.0 0.47" />
        <parent link="world" />
        <child link="box_link" />
    </joint>
    <!-- sub-link defining detailed meshes for collision with environment -->
    <link name="panda_link0">
        <visual>
            <geometry>
                <mesh filename="package://franka_description/meshes/visual/link0.dae" />
            </geometry>
        </visual>
        <collision>
            <geometry>
                <mesh filename="package://franka_description/meshes/collision/link0.stl" />
            </geometry>
        </collision>
        <inertial>
            <mass value="0.1" />
            <origin xyz="0 0 0" rpy="0 0 0" />
            <inertia ixx="0.03" iyy="0.03" izz="0.03" ixy="0.0" ixz="0.0" iyz="0.0" />
        </inertial>
    </link>
    <!-- sub-link defining coarse geometries of real robot's internal self-collision -->
    <link name="panda_link0_sc">
        <collision>
            <origin rpy="0 1.5707963267948966 0" xyz="-0.075 0 0.06" />
            <geometry>
                <cylinder length="0.03" radius="0.09" />
            </geometry>
        </collision>
        <collision>
            <origin xyz="-0.06 0 0.06" />
            <geometry>
                <sphere radius="0.09" />
            </geometry>
        </collision>
        <collision>
            <origin xyz="-0.09 0 0.06" />
            <geometry>
                <sphere radius="0.09" />
            </geometry>
        </collision>
        <inertial>
            <mass value="0.1" />
            <origin xyz="0 0 0" rpy="0 0 0" />
            <inertia ixx="0.03" iyy="0.03" izz="0.03" ixy="0.0" ixz="0.0" iyz="0.0" />
        </inertial>
    </link>
    <!-- fixed joint between both sub-links -->
    <joint name="panda_link0_sc_joint" type="fixed">
        <origin rpy="0 0 0" />
        <parent link="panda_link0" />
        <child link="panda_link0_sc" />
    </joint>
    <!-- sub-link defining detailed meshes for collision with environment -->
    <link name="panda_link1">
        <visual>
            <geometry>
                <mesh filename="package://franka_description/meshes/visual/link1.dae" />
            </geometry>
        </visual>
        <collision>
            <geometry>
                <mesh filename="package://franka_description/meshes/collision/link1.stl" />
            </geometry>
        </collision>
        <inertial>
            <mass value="0.1" />
            <origin xyz="0 0 0" rpy="0 0 0" />
            <inertia ixx="0.03" iyy="0.03" izz="0.03" ixy="0.0" ixz="0.0" iyz="0.0" />
        </inertial>
    </link>
    <!-- sub-link defining coarse geometries of real robot's internal self-collision -->
    <link name="panda_link1_sc">
        <collision>
            <origin rpy="0 0 0" xyz="0 0 -0.1915" />
            <geometry>
                <cylinder length="0.283" radius="0.09" />
            </geometry>
        </collision>
        <collision>
            <origin xyz="0 0 -0.05000000000000002" />
            <geometry>
                <sphere radius="0.09" />
            </geometry>
        </collision>
        <collision>
            <origin xyz="0 0 -0.33299999999999996" />
            <geometry>
                <sphere radius="0.09" />
            </geometry>
        </collision>
        <inertial>
            <mass value="0.1" />
            <origin xyz="0 0 0" rpy="0 0 0" />
            <inertia ixx="0.03" iyy="0.03" izz="0.03" ixy="0.0" ixz="0.0" iyz="0.0" />
        </inertial>
    </link>
    <!-- fixed joint between both sub-links -->
    <joint name="panda_link1_sc_joint" type="fixed">
        <origin rpy="0 0 0" />
        <parent link="panda_link1" />
        <child link="panda_link1_sc" />
    </joint>
    <joint name="panda_joint1" type="revolute">
        <origin rpy="0 0 0" xyz="0 0 0.333" />
        <parent link="panda_link0" />
        <child link="panda_link1" />
        <axis xyz="0 0 1" />
        <limit effort="87.0" lower="-2.8973" upper="2.8973" velocity="2.175" />
        <safety_controller k_position="100.0" k_velocity="40.0" soft_lower_limit="-2.8973" soft_upper_limit="2.8973" />
        <dynamics D="1" K="7000" damping="0.003" friction="0.0" mu_coulomb="0" mu_viscous="16" />
    </joint>
    <!-- sub-link defining detailed meshes for collision with environment -->
    <link name="panda_link2">
        <visual>
            <geometry>
                <mesh filename="package://franka_description/meshes/visual/link2.dae" />
            </geometry>
        </visual>
        <collision>
            <geometry>
                <mesh filename="package://franka_description/meshes/collision/link2.stl" />
            </geometry>
        </collision>
        <inertial>
            <mass value="0.1" />
            <origin xyz="0 0 0" rpy="0 0 0" />
            <inertia ixx="0.03" iyy="0.03" izz="0.03" ixy="0.0" ixz="0.0" iyz="0.0" />
        </inertial>
    </link>
    <!-- sub-link defining coarse geometries of real robot's internal self-collision -->
    <link name="panda_link2_sc">
        <collision>
            <origin rpy="0 0 0" xyz="0 0 0" />
            <geometry>
                <cylinder length="0.12" radius="0.09" />
            </geometry>
        </collision>
        <collision>
            <origin xyz="0 0 0.06" />
            <geometry>
                <sphere radius="0.09" />
            </geometry>
        </collision>
        <collision>
            <origin xyz="0 0 -0.06" />
            <geometry>
                <sphere radius="0.09" />
            </geometry>
        </collision>
        <inertial>
            <mass value="0.1" />
            <origin xyz="0 0 0" rpy="0 0 0" />
            <inertia ixx="0.03" iyy="0.03" izz="0.03" ixy="0.0" ixz="0.0" iyz="0.0" />
        </inertial>
    </link>
    <!-- fixed joint between both sub-links -->
    <joint name="panda_link2_sc_joint" type="fixed">
        <origin rpy="0 0 0" />
        <parent link="panda_link2" />
        <child link="panda_link2_sc" />
    </joint>
    <joint name="panda_joint2" type="revolute">
        <origin rpy="-1.5707963267948966 0 0" xyz="0 0 0" />
        <parent link="panda_link1" />
        <child link="panda_link2" />
        <axis xyz="0 0 1" />
        <limit effort="87.0" lower="-1.7628" upper="1.7628" velocity="2.175" />
        <safety_controller k_position="100.0" k_velocity="40.0" soft_lower_limit="-1.7628" soft_upper_limit="1.7628" />
        <dynamics D="1" K="7000" damping="0.003" friction="0.0" mu_coulomb="0" mu_viscous="16" />
    </joint>
    <!-- sub-link defining detailed meshes for collision with environment -->
    <link name="panda_link3">
        <visual>
            <geometry>
                <mesh filename="package://franka_description/meshes/visual/link3.dae" />
            </geometry>
        </visual>
        <collision>
            <geometry>
                <mesh filename="package://franka_description/meshes/collision/link3.stl" />
            </geometry>
        </collision>
        <inertial>
            <mass value="0.1" />
            <origin xyz="0 0 0" rpy="0 0 0" />
            <inertia ixx="0.03" iyy="0.03" izz="0.03" ixy="0.0" ixz="0.0" iyz="0.0" />
        </inertial>
    </link>
    <!-- sub-link defining coarse geometries of real robot's internal self-collision -->
    <link name="panda_link3_sc">
        <collision>
            <origin rpy="0 0 0" xyz="0 0 -0.145" />
            <geometry>
                <cylinder length="0.15" radius="0.09" />
            </geometry>
        </collision>
        <collision>
            <origin xyz="0 0 -0.06999999999999999" />
            <geometry>
                <sphere radius="0.09" />
            </geometry>
        </collision>
        <collision>
            <origin xyz="0 0 -0.21999999999999997" />
            <geometry>
                <sphere radius="0.09" />
            </geometry>
        </collision>
        <inertial>
            <mass value="0.1" />
            <origin xyz="0 0 0" rpy="0 0 0" />
            <inertia ixx="0.03" iyy="0.03" izz="0.03" ixy="0.0" ixz="0.0" iyz="0.0" />
        </inertial>
    </link>
    <!-- fixed joint between both sub-links -->
    <joint name="panda_link3_sc_joint" type="fixed">
        <origin rpy="0 0 0" />
        <parent link="panda_link3" />
        <child link="panda_link3_sc" />
    </joint>
    <joint name="panda_joint3" type="revolute">
        <origin rpy="1.5707963267948966 0 0" xyz="0 -0.316 0" />
        <parent link="panda_link2" />
        <child link="panda_link3" />
        <axis xyz="0 0 1" />
        <limit effort="87.0" lower="-2.8973" upper="2.8973" velocity="2.175" />
        <safety_controller k_position="100.0" k_velocity="40.0" soft_lower_limit="-2.8973" soft_upper_limit="2.8973" />
        <dynamics D="1" K="7000" damping="0.003" friction="0.0" mu_coulomb="0" mu_viscous="16" />
    </joint>
    <!-- sub-link defining detailed meshes for collision with environment -->
    <link name="panda_link4">
        <visual>
            <geometry>
                <mesh filename="package://franka_description/meshes/visual/link4.dae" />
            </geometry>
        </visual>
        <collision>
            <geometry>
                <mesh filename="package://franka_description/meshes/collision/link4.stl" />
            </geometry>
        </collision>
        <inertial>
            <mass value="0.1" />
            <origin xyz="0 0 0" rpy="0 0 0" />
            <inertia ixx="0.03" iyy="0.03" izz="0.03" ixy="0.0" ixz="0.0" iyz="0.0" />
        </inertial>
    </link>
    <!-- sub-link defining coarse geometries of real robot's internal self-collision -->
    <link name="panda_link4_sc">
        <collision>
            <origin rpy="0 0 0" xyz="0 0 0" />
            <geometry>
                <cylinder length="0.12" radius="0.09" />
            </geometry>
        </collision>
        <collision>
            <origin xyz="0 0 0.06" />
            <geometry>
                <sphere radius="0.09" />
            </geometry>
        </collision>
        <collision>
            <origin xyz="0 0 -0.06" />
            <geometry>
                <sphere radius="0.09" />
            </geometry>
        </collision>
        <inertial>
            <mass value="0.1" />
            <origin xyz="0 0 0" rpy="0 0 0" />
            <inertia ixx="0.03" iyy="0.03" izz="0.03" ixy="0.0" ixz="0.0" iyz="0.0" />
        </inertial>
    </link>
    <!-- fixed joint between both sub-links -->
    <joint name="panda_link4_sc_joint" type="fixed">
        <origin rpy="0 0 0" />
        <parent link="panda_link4" />
        <child link="panda_link4_sc" />
    </joint>
    <joint name="panda_joint4" type="revolute">
        <origin rpy="1.5707963267948966 0 0" xyz="0.0825 0 0" />
        <parent link="panda_link3" />
        <child link="panda_link4" />
        <axis xyz="0 0 1" />
        <limit effort="87.0" lower="-3.0718" upper="-0.0698" velocity="2.175" />
        <safety_controller k_position="100.0" k_velocity="40.0" soft_lower_limit="-3.0718" soft_upper_limit="-0.0698" />
        <dynamics D="1" K="7000" damping="0.003" friction="0.0" mu_coulomb="0" mu_viscous="16" />
    </joint>
    <!-- sub-link defining detailed meshes for collision with environment -->
    <link name="panda_link5">
        <visual>
            <geometry>
                <mesh filename="package://franka_description/meshes/visual/link5.dae" />
            </geometry>
        </visual>
        <collision>
            <geometry>
                <mesh filename="package://franka_description/meshes/collision/link5.stl" />
            </geometry>
        </collision>
        <inertial>
            <mass value="0.1" />
            <origin xyz="0 0 0" rpy="0 0 0" />
            <inertia ixx="0.03" iyy="0.03" izz="0.03" ixy="0.0" ixz="0.0" iyz="0.0" />
        </inertial>
    </link>
    <!-- sub-link defining coarse geometries of real robot's internal self-collision -->
    <link name="panda_link5_sc">
        <collision>
            <origin rpy="0 0 0" xyz="0 0 -0.26" />
            <geometry>
                <cylinder length="0.1" radius="0.09" />
            </geometry>
        </collision>
        <collision>
            <origin xyz="0 0 -0.21000000000000002" />
            <geometry>
                <sphere radius="0.09" />
            </geometry>
        </collision>
        <collision>
            <origin xyz="0 0 -0.31" />
            <geometry>
                <sphere radius="0.09" />
            </geometry>
        </collision>
        <collision>
            <origin rpy="0 0 0.08" xyz="0 0.08 -0.13" />
            <geometry>
                <cylinder length="0.14" radius="0.055" />
            </geometry>
        </collision>
        <collision>
            <origin xyz="0 0.08 -0.06" />
            <geometry>
                <sphere radius="0.055" />
            </geometry>
        </collision>
        <collision>
            <origin xyz="0 0.08 -0.2" />
            <geometry>
                <sphere radius="0.055" />
            </geometry>
        </collision>
        <inertial>
            <mass value="0.1" />
            <origin xyz="0 0 0" rpy="0 0 0" />
            <inertia ixx="0.03" iyy="0.03" izz="0.03" ixy="0.0" ixz="0.0" iyz="0.0" />
        </inertial>
    </link>
    <!-- fixed joint between both sub-links -->
    <joint name="panda_link5_sc_joint" type="fixed">
        <origin rpy="0 0 0" />
        <parent link="panda_link5" />
        <child link="panda_link5_sc" />
    </joint>
    <joint name="panda_joint5" type="revolute">
        <origin rpy="-1.5707963267948966 0 0" xyz="-0.0825 0.384 0" />
        <parent link="panda_link4" />
        <child link="panda_link5" />
        <axis xyz="0 0 1" />
        <limit effort="12.0" lower="-2.8973" upper="2.8973" velocity="2.61" />
        <safety_controller k_position="100.0" k_velocity="40.0" soft_lower_limit="-2.8973" soft_upper_limit="2.8973" />
        <dynamics D="1" K="7000" damping="0.003" friction="0.0" mu_coulomb="0" mu_viscous="16" />
    </joint>
    <!-- sub-link defining detailed meshes for collision with environment -->
    <link name="panda_link6">
        <visual>
            <geometry>
                <mesh filename="package://franka_description/meshes/visual/link6.dae" />
            </geometry>
        </visual>
        <collision>
            <geometry>
                <mesh filename="package://franka_description/meshes/collision/link6.stl" />
            </geometry>
        </collision>
        <inertial>
            <mass value="0.1" />
            <origin xyz="0 0 0" rpy="0 0 0" />
            <inertia ixx="0.03" iyy="0.03" izz="0.03" ixy="0.0" ixz="0.0" iyz="0.0" />
        </inertial>
    </link>
    <!-- sub-link defining coarse geometries of real robot's internal self-collision -->
    <link name="panda_link6_sc">
        <collision>
            <origin rpy="0 0 0" xyz="0 0 -0.03" />
            <geometry>
                <cylinder length="0.08" radius="0.08" />
            </geometry>
        </collision>
        <collision>
            <origin xyz="0 0 0.010000000000000002" />
            <geometry>
                <sphere radius="0.08" />
            </geometry>
        </collision>
        <collision>
            <origin xyz="0 0 -0.07" />
            <geometry>
                <sphere radius="0.08" />
            </geometry>
        </collision>
        <inertial>
            <mass value="0.1" />
            <origin xyz="0 0 0" rpy="0 0 0" />
            <inertia ixx="0.03" iyy="0.03" izz="0.03" ixy="0.0" ixz="0.0" iyz="0.0" />
        </inertial>
    </link>
    <!-- fixed joint between both sub-links -->
    <joint name="panda_link6_sc_joint" type="fixed">
        <origin rpy="0 0 0" />
        <parent link="panda_link6" />
        <child link="panda_link6_sc" />
    </joint>
    <joint name="panda_joint6" type="revolute">
        <origin rpy="1.5707963267948966 0 0" xyz="0 0 0" />
        <parent link="panda_link5" />
        <child link="panda_link6" />
        <axis xyz="0 0 1" />
        <limit effort="12.0" lower="-0.0175" upper="3.7525" velocity="2.61" />
        <safety_controller k_position="100.0" k_velocity="40.0" soft_lower_limit="-0.0175" soft_upper_limit="3.7525" />
        <dynamics D="1" K="7000" damping="0.003" friction="0.0" mu_coulomb="0" mu_viscous="16" />
    </joint>
    <!-- sub-link defining detailed meshes for collision with environment -->
    <link name="panda_link7">
        <visual>
            <geometry>
                <mesh filename="package://franka_description/meshes/visual/link7.dae" />
            </geometry>
        </visual>
        <collision>
            <geometry>
                <mesh filename="package://franka_description/meshes/collision/link7.stl" />
            </geometry>
        </collision>
        <inertial>
            <mass value="0.1" />
            <origin xyz="0 0 0" rpy="0 0 0" />
            <inertia ixx="0.03" iyy="0.03" izz="0.03" ixy="0.0" ixz="0.0" iyz="0.0" />
        </inertial>
    </link>
    <!-- sub-link defining coarse geometries of real robot's internal self-collision -->
    <link name="panda_link7_sc">
        <collision>
            <origin rpy="0 0 0" xyz="0 0 0.01" />
            <geometry>
                <cylinder length="0.14" radius="0.07" />
            </geometry>
        </collision>
        <collision>
            <origin xyz="0 0 0.08" />
            <geometry>
                <sphere radius="0.07" />
            </geometry>
        </collision>
        <collision>
            <origin xyz="0 0 -0.060000000000000005" />
            <geometry>
                <sphere radius="0.07" />
            </geometry>
        </collision>
        <collision>
            <origin rpy="0 1.5707963267948966 0" xyz="0.06 0 0.082" />
            <geometry>
                <cylinder length="0.01" radius="0.06" />
            </geometry>
        </collision>
        <collision>
            <origin xyz="0.065 0 0.082" />
            <geometry>
                <sphere radius="0.06" />
            </geometry>
        </collision>
        <collision>
            <origin xyz="0.055 0 0.082" />
            <geometry>
                <sphere radius="0.06" />
            </geometry>
        </collision>
        <inertial>
            <mass value="0.1" />
            <origin xyz="0 0 0" rpy="0 0 0" />
            <inertia ixx="0.03" iyy="0.03" izz="0.03" ixy="0.0" ixz="0.0" iyz="0.0" />
        </inertial>
    </link>
    <!-- fixed joint between both sub-links -->
    <joint name="panda_link7_sc_joint" type="fixed">
        <origin rpy="0 0 0.7853981633974483" />
        <parent link="panda_link7" />
        <child link="panda_link7_sc" />
    </joint>
    <joint name="panda_joint7" type="revolute">
        <origin rpy="1.5707963267948966 0 0" xyz="0.088 0 0" />
        <parent link="panda_link6" />
        <child link="panda_link7" />
        <axis xyz="0 0 1" />
        <limit effort="12.0" lower="-2.8973" upper="2.8973" velocity="2.61" />
        <safety_controller k_position="100.0" k_velocity="40.0" soft_lower_limit="-2.8973" soft_upper_limit="2.8973" />
        <dynamics D="1" K="7000" damping="0.003" friction="0.0" mu_coulomb="0" mu_viscous="16" />
    </joint>
    <link name="panda_link8" />
    <joint name="panda_joint8" type="fixed">
        <origin rpy="0 0 0" xyz="0 0 0.107" />
        <parent link="panda_link7" />
        <child link="panda_link8" />
    </joint>
    <joint name="panda_joint" type="fixed">
        <origin rpy="0.0 0.0 0.0" xyz="0.12 0.0 0.47" />
        <origin rpy="0.0 0.0 0.0" xyz="0.12 0.0 0.0" />
        <parent link="box_link" />
        <child link="panda_link0" />
    </joint>
    <!-- <joint
    name="panda_link8_to_root_link_joint" type="fixed">
    <origin xyz="0.0 0.0 0.0" rpy="0.0 0.0 0.0" />
    <parent link="panda_link8" />
    <child link="root_link" />
  </joint>

  <link name="root_link" /> -->
    <joint name="qbhand1_base_fixed_joint" type="fixed">
        <origin rpy="1.57 0 1.57" xyz="0.045 0 0.035" />
        <parent link="panda_link8" />
        <child link="qbhand1_base_link" />
    </joint>
    <link name="qbhand1_base_link">
        <inertial>
            <mass value="0.45" />
            <origin rpy="0 0 0" xyz="0.0030 -0.0449 0.0135" />
            <inertia ixx="0.00045" ixy="0.0" ixz="0.0" iyy="0.0006" iyz="0.0" izz="0.00025" />
        </inertial>
        <visual>
            <origin rpy="0 0 0" xyz="0 0 0" />
            <geometry>
                <mesh filename="package://qb_hand_description/meshes/flange_iso_04.stl" scale="0.001 0.001 0.001" />
            </geometry>
            <material name="qbhand/base" />
        </visual>
        <collision>
            <origin rpy="0 0 0" xyz="0 0 0" />
            <geometry>
                <mesh filename="package://qb_hand_description/meshes/flange_iso_04.stl" scale="0.001 0.001 0.001" />
            </geometry>
        </collision>
    </link>
    <gazebo reference="qbhand1_base_link">
        <self_collide>1</self_collide>
        <!-- TODO: add other Gazebo Link properties (http://sdformat.org/spec?elem=link) -->
        <!--      <collision>-->
        <!--        <surface>-->
        <!--          <contact>-->
        <!--            <ode>-->
        <!--              <kp>1.0</kp>-->
        <!--              <kd>0.01</kd>-->
        <!--              <max_vel>0.0</max_vel>-->
        <!--              <min_depth>0.001</min_depth>-->
        <!--            </ode>-->
        <!--          </contact>-->
        <!--          <friction>-->
        <!--            <ode>-->
        <!--              <mu>0.9</mu>-->
        <!--              <mu2>0.9</mu2>-->
        <!--            </ode>-->
        <!--          </friction>-->
        <!--        </surface>-->
        <!--      </collision>-->
        <plugin name="gazebo_ros_control" filename="libgazebo_ros_control.so">
            <robotNamespace>/</robotNamespace>
        </plugin>
    </gazebo>
    <joint name="qbhand1_90_deg_flange_base_fixed_joint" type="fixed">
        <origin rpy="-1.57 0 0" xyz="0 0 0" />
        <parent link="qbhand1_base_link" />
        <child link="qbhand1_90_deg_flange_base_link" />
    </joint>
    <link name="qbhand1_90_deg_flange_base_link">
        <inertial>
            <mass value="0.205" />
            <origin rpy="0 0 1.57" xyz="0.0 7.8738498e-04 1.5878899e-02" />
            <inertia ixx="0.00012506929" ixy="0.0" ixz="0.0" iyy="0.0001338779" iyz="0.0" izz="0.00019218394" />
        </inertial>
        <visual>
            <origin rpy="0 0 0" xyz="0 0 0" />
            <geometry>
                <mesh filename="package://qb_hand_description/meshes/flange_deg_90.stl" scale="0.001 0.001 0.001" />
            </geometry>
            <material name="qbhand/90_deg_flange_base" />
        </visual>
        <collision>
            <origin rpy="0 0 0" xyz="0 0 0" />
            <geometry>
                <mesh filename="package://qb_hand_description/meshes/flange_deg_90.stl" scale="0.001 0.001 0.001" />
            </geometry>
        </collision>
    </link>
    <gazebo reference="qbhand1_90_deg_flange_base_link">
        <self_collide>1</self_collide>
        <!-- TODO: add other Gazebo Link properties (http://sdformat.org/spec?elem=link) -->
        <!--      <collision>-->
        <!--        <surface>-->
        <!--          <contact>-->
        <!--            <ode>-->
        <!--              <kp>1.0</kp>-->
        <!--              <kd>0.01</kd>-->
        <!--              <max_vel>0.0</max_vel>-->
        <!--              <min_depth>0.001</min_depth>-->
        <!--            </ode>-->
        <!--          </contact>-->
        <!--          <friction>-->
        <!--            <ode>-->
        <!--              <mu>0.9</mu>-->
        <!--              <mu2>0.9</mu2>-->
        <!--            </ode>-->
        <!--          </friction>-->
        <!--        </surface>-->
        <!--      </collision>-->
    </gazebo>
    <joint name="qbhand1_palm_fixed_joint" type="fixed">
        <origin rpy="1.57 0 0" xyz="-0.0045 0.0145 0.144" />
        <parent link="qbhand1_base_link" />
        <child link="qbhand1_palm_link" />
    </joint>
    <link name="qbhand1_palm_link">
        <inertial>
            <mass value="0.45" />
            <origin rpy="0 0 0" xyz="0.0030 -0.0449 0.0135" />
            <inertia ixx="0.00045" ixy="0.0" ixz="0.0" iyy="0.0006" iyz="0.0" izz="0.00025" />
        </inertial>
        <visual>
            <origin rpy="0 0 0" xyz="0 0 0" />
            <geometry>
                <mesh filename="package://qb_hand_description/meshes/palm_pinch_r.stl" scale="0.001 0.001 0.001" />
            </geometry>
            <material name="qbhand/palm" />
        </visual>
        <collision>
            <origin rpy="0 0 0" xyz="0 0 0" />
            <geometry>
                <mesh filename="package://qb_hand_description/meshes/palm_pinch_r.stl" scale="0.001 0.001 0.001" />
            </geometry>
        </collision>
    </link>
    <gazebo reference="qbhand1_palm_link">
        <self_collide>1</self_collide>
        <!-- TODO: add other Gazebo Link properties (http://sdformat.org/spec?elem=link) -->
        <!--      <collision>-->
        <!--        <surface>-->
        <!--          <contact>-->
        <!--            <ode>-->
        <!--              <kp>1.0</kp>-->
        <!--              <kd>0.01</kd>-->
        <!--              <max_vel>0.0</max_vel>-->
        <!--              <min_depth>0.001</min_depth>-->
        <!--            </ode>-->
        <!--          </contact>-->
        <!--          <friction>-->
        <!--            <ode>-->
        <!--              <mu>0.9</mu>-->
        <!--              <mu2>0.9</mu2>-->
        <!--            </ode>-->
        <!--          </friction>-->
        <!--        </surface>-->
        <!--      </collision>-->
    </gazebo>
    <joint name="qbhand1_synergy_joint" type="revolute">
        <origin rpy="0 0 0" xyz="0 0 0" />
        <parent link="qbhand1_palm_link" />
        <child link="qbhand1_synergy_tendon_virtual_link" />
        <axis xyz="0 0 1" />
        <dynamics damping="0.0" friction="0.0" />
        <limit effort="100" lower="0.0" upper="1.0" velocity="100" />
    </joint>
    <transmission name="qbhand1_synergy_transmission">
        <type>transmission_interface/qbMoveTransmission</type>
        <joint name="qbhand1_synergy_joint">
            <hardwareInterface>hardware_interface/EffortJointInterface</hardwareInterface>
        </joint>
        <actuator name="qbhand1_synergy_joint">
            <hardwareInterface>hardware_interface/EffortJointInterface</hardwareInterface>
        </actuator>
    </transmission>
    <link name="qbhand1_synergy_tendon_virtual_link">
        <inertial>
            <origin rpy="0 0 0" xyz="0 0 0" />
            <mass value="1e-4" />
            <inertia ixx="1e-9" ixy="0.0" ixz="0.0" iyy="1e-9" iyz="0.0" izz="1e-9" />
        </inertial>
    </link>
    <joint name="qbhand1_thumb_knuckle_joint" type="revolute">
        <origin rpy="-1.57 3.14 0.0" xyz="-0.044 -0.0465 -0.002" />
        <parent link="qbhand1_palm_link" />
        <child link="qbhand1_thumb_knuckle_link" />
        <axis xyz="0 0 -1" />
        <dynamics damping="0.0" friction="0.0" />
        <limit effort="100" lower="0.0" upper="1.571" velocity="100" />
        <mimic joint="qbhand1_synergy_joint" multiplier="2.542" />
    </joint>
    <transmission name="qbhand1_transmission">
        <type>transmission_interface/qbMoveTransmission</type>
        <joint name="qbhand1_thumb_knuckle_joint">
            <hardwareInterface>hardware_interface/EffortJointInterface</hardwareInterface>
        </joint>
        <actuator name="qbhand1_thumb_knuckle_joint">
            <hardwareInterface>hardware_interface/EffortJointInterface</hardwareInterface>
        </actuator>
    </transmission>
    <gazebo reference="qbhand1_thumb_knuckle_joint">
        <!-- TODO: add other Gazebo Joint properties (http://sdformat.org/spec?elem=joint) -->
    </gazebo>
    <link name="qbhand1_thumb_knuckle_link">
        <inertial>
            <mass value="0.01" />
            <origin rpy="0 0 0" xyz="1.3071561e-02 -2.7357764e-03 6.4347823e-04" />
            <inertia ixx="3.5865978e-07" ixy="2.0944224e-07" ixz="-6.8657569e-08" iyy="1.3885564e-06" iyz="3.2170608e-08" izz="1.3571203e-06" />
        </inertial>
        <visual>
            <origin rpy="0 0 0" xyz="0 0 0" />
            <geometry>
                <mesh filename="package://qb_hand_description/meshes/ph_thumb_r.stl" scale="0.001 0.001 0.001" />
            </geometry>
            <material name="qbhand/knuckle" />
        </visual>
        <collision>
            <origin rpy="0 0 0" xyz="0 0 0" />
            <geometry>
                <mesh filename="package://qb_hand_description/meshes/ph_thumb_r_collision.stl" scale="0.001 0.001 0.001" />
            </geometry>
        </collision>
    </link>
    <gazebo reference="qbhand1_thumb_knuckle_link">
        <self_collide>1</self_collide>
        <!-- TODO: add other Gazebo Link properties (http://sdformat.org/spec?elem=link) -->
        <!--      <collision>-->
        <!--        <surface>-->
        <!--          <contact>-->
        <!--            <ode>-->
        <!--              <kp>1.0</kp>-->
        <!--              <kd>0.01</kd>-->
        <!--              <max_vel>0.0</max_vel>-->
        <!--              <min_depth>0.001</min_depth>-->
        <!--            </ode>-->
        <!--          </contact>-->
        <!--          <friction>-->
        <!--            <ode>-->
        <!--              <mu>0.9</mu>-->
        <!--              <mu2>0.9</mu2>-->
        <!--            </ode>-->
        <!--          </friction>-->
        <!--        </surface>-->
        <!--      </collision>-->
    </gazebo>
    <joint name="qbhand1_thumb_proximal_joint" type="revolute">
        <origin rpy="-1.1415 0.0 0.0" xyz="0.0255 -0.0038 -0.00012" />
        <parent link="qbhand1_thumb_knuckle_link" />
        <child link="qbhand1_thumb_proximal_virtual_link" />
        <axis xyz="0 0 -1" />
        <dynamics damping="0.0" friction="0.0" />
        <limit effort="100" lower="0.0" upper="0.785" velocity="100" />
        <mimic joint="qbhand1_synergy_joint" multiplier="0.785" />
    </joint>
    <transmission name="qbhand1_transmission">
        <type>transmission_interface/qbMoveTransmission</type>
        <joint name="qbhand1_thumb_proximal_joint">
            <hardwareInterface>hardware_interface/EffortJointInterface</hardwareInterface>
        </joint>
        <actuator name="qbhand1_thumb_proximal_joint">
            <hardwareInterface>hardware_interface/EffortJointInterface</hardwareInterface>
        </actuator>
    </transmission>
    <gazebo reference="qbhand1_thumb_proximal_joint">
        <!-- TODO: add other Gazebo Joint properties (http://sdformat.org/spec?elem=joint) -->
    </gazebo>
    <link name="qbhand1_thumb_proximal_virtual_link">
        <inertial>
            <origin rpy="0 0 0" xyz="0 0 0" />
            <mass value="1e-4" />
            <inertia ixx="1e-9" ixy="0.0" ixz="0.0" iyy="1e-9" iyz="0.0" izz="1e-9" />
        </inertial>
    </link>
    <joint name="qbhand1_thumb_proximal_virtual_joint" type="revolute">
        <origin rpy="0 0 0" xyz="0.013 0 0" />
        <parent link="qbhand1_thumb_proximal_virtual_link" />
        <child link="qbhand1_thumb_proximal_link" />
        <axis xyz="0 0 -1" />
        <dynamics damping="0.0" friction="0.0" />
        <limit effort="100" lower="0.0" upper="0.785" velocity="100" />
        <mimic joint="qbhand1_thumb_proximal_joint" multiplier="1.0" />
    </joint>
    <transmission name="qbhand1_transmission">
        <type>transmission_interface/qbMoveTransmission</type>
        <joint name="qbhand1_thumb_proximal_virtual_joint">
            <hardwareInterface>hardware_interface/EffortJointInterface</hardwareInterface>
        </joint>
        <actuator name="qbhand1_thumb_proximal_virtual_joint">
            <hardwareInterface>hardware_interface/EffortJointInterface</hardwareInterface>
        </actuator>
    </transmission>
    <gazebo reference="qbhand1_thumb_proximal_virtual_joint">
        <!-- TODO: add other Gazebo Joint properties (http://sdformat.org/spec?elem=joint) -->
    </gazebo>
    <link name="qbhand1_thumb_proximal_link">
        <inertial>
            <mass value="0.0063" />
            <origin rpy="0 0 0" xyz="4.7601567e-03 -1.3786947e-03 0.0" />
            <inertia ixx="1.8024201e-07" ixy="5.756798e-09" ixz="0.0" iyy="2.3516266e-07" iyz="0.0" izz="2.691504e-07" />
        </inertial>
        <visual>
            <origin rpy="0 0 0" xyz="0 0 0" />
            <geometry>
                <mesh filename="package://qb_hand_description/meshes/ph_short.stl" scale="0.001 0.001 0.001" />
            </geometry>
            <material name="qbhand/proximal" />
        </visual>
        <collision>
            <origin rpy="0 0 0" xyz="0 0 0" />
            <geometry>
                <mesh filename="package://qb_hand_description/meshes/ph_short_collision.stl" scale="0.001 0.001 0.001" />
            </geometry>
        </collision>
    </link>
    <gazebo reference="qbhand1_thumb_proximal_link">
        <self_collide>1</self_collide>
        <!-- TODO: add other Gazebo Link properties (http://sdformat.org/spec?elem=link) -->
        <!--      <collision>-->
        <!--        <surface>-->
        <!--          <contact>-->
        <!--            <ode>-->
        <!--              <kp>1.0</kp>-->
        <!--              <kd>0.01</kd>-->
        <!--              <max_vel>0.0</max_vel>-->
        <!--              <min_depth>0.001</min_depth>-->
        <!--            </ode>-->
        <!--          </contact>-->
        <!--          <friction>-->
        <!--            <ode>-->
        <!--              <mu>0.9</mu>-->
        <!--              <mu2>0.9</mu2>-->
        <!--            </ode>-->
        <!--          </friction>-->
        <!--        </surface>-->
        <!--      </collision>-->
    </gazebo>
    <joint name="qbhand1_thumb_distal_joint" type="revolute">
        <origin rpy="0 0 0" xyz="0.009 0 0" />
        <parent link="qbhand1_thumb_proximal_link" />
        <child link="qbhand1_thumb_distal_virtual_link" />
        <axis xyz="0 0 -1" />
        <dynamics damping="0.0" friction="0.0" />
        <limit effort="100" lower="0.0" upper="0.785" velocity="100" />
        <mimic joint="qbhand1_synergy_joint" multiplier="0.785" />
    </joint>
    <transmission name="qbhand1_transmission">
        <type>transmission_interface/qbMoveTransmission</type>
        <joint name="qbhand1_thumb_distal_joint">
            <hardwareInterface>hardware_interface/EffortJointInterface</hardwareInterface>
        </joint>
        <actuator name="qbhand1_thumb_distal_joint">
            <hardwareInterface>hardware_interface/EffortJointInterface</hardwareInterface>
        </actuator>
    </transmission>
    <gazebo reference="qbhand1_thumb_distal_joint">
        <!-- TODO: add other Gazebo Joint properties (http://sdformat.org/spec?elem=joint) -->
    </gazebo>
    <link name="qbhand1_thumb_distal_virtual_link">
        <inertial>
            <origin rpy="0 0 0" xyz="0 0 0" />
            <mass value="1e-4" />
            <inertia ixx="1e-9" ixy="0.0" ixz="0.0" iyy="1e-9" iyz="0.0" izz="1e-9" />
        </inertial>
    </link>
    <joint name="qbhand1_thumb_distal_virtual_joint" type="revolute">
        <origin rpy="0 0 0" xyz="0.013 0 0" />
        <parent link="qbhand1_thumb_distal_virtual_link" />
        <child link="qbhand1_thumb_distal_link" />
        <axis xyz="0 0 -1" />
        <dynamics damping="0.0" friction="0.0" />
        <limit effort="100" lower="0.0" upper="0.785" velocity="100" />
        <mimic joint="qbhand1_thumb_distal_joint" multiplier="1.0" />
    </joint>
    <transmission name="qbhand1_transmission">
        <type>transmission_interface/qbMoveTransmission</type>
        <joint name="qbhand1_thumb_distal_virtual_joint">
            <hardwareInterface>hardware_interface/EffortJointInterface</hardwareInterface>
        </joint>
        <actuator name="qbhand1_thumb_distal_virtual_joint">
            <hardwareInterface>hardware_interface/EffortJointInterface</hardwareInterface>
        </actuator>
    </transmission>
    <gazebo reference="qbhand1_thumb_distal_virtual_joint">
        <!-- TODO: add other Gazebo Joint properties (http://sdformat.org/spec?elem=joint) -->
    </gazebo>
    <link name="qbhand1_thumb_distal_link">
        <inertial>
            <mass value="0.009" />
            <origin rpy="0 0 0" xyz="8.8025467e-03 -1.7219289e-03 0.0" />
            <inertia ixx="2.6586142e-07" ixy="1.2416847e-08" ixz="0.0" iyy="5.9935767e-07" iyz="0.0" izz="6.6781963e-07" />
        </inertial>
        <visual>
            <origin rpy="0 0 0" xyz="0 0 0" />
            <geometry>
                <mesh filename="package://qb_hand_description/meshes/ph_distal.stl" scale="0.001 0.001 0.001" />
            </geometry>
            <material name="qbhand/distal" />
        </visual>
        <collision>
            <origin rpy="0 0 0" xyz="0 0 0" />
            <geometry>
                <mesh filename="package://qb_hand_description/meshes/ph_distal_collision.stl" scale="0.001 0.001 0.001" />
            </geometry>
        </collision>
    </link>
    <gazebo reference="qbhand1_thumb_distal_link">
        <self_collide>1</self_collide>
        <!-- TODO: add other Gazebo Link properties (http://sdformat.org/spec?elem=link) -->
        <!--      <collision>-->
        <!--        <surface>-->
        <!--          <contact>-->
        <!--            <ode>-->
        <!--              <kp>1.0</kp>-->
        <!--              <kd>0.01</kd>-->
        <!--              <max_vel>0.0</max_vel>-->
        <!--              <min_depth>0.001</min_depth>-->
        <!--            </ode>-->
        <!--          </contact>-->
        <!--          <friction>-->
        <!--            <ode>-->
        <!--              <mu>0.9</mu>-->
        <!--              <mu2>0.9</mu2>-->
        <!--            </ode>-->
        <!--          </friction>-->
        <!--        </surface>-->
        <!--      </collision>-->
    </gazebo>
    <joint name="qbhand1_index_knuckle_joint" type="revolute">
        <origin rpy="0 0 1.57" xyz="-0.02 -0.007 0.014" />
        <parent link="qbhand1_palm_link" />
        <child link="qbhand1_index_knuckle_link" />
        <axis xyz="0 0 -1" />
        <dynamics damping="0.0" friction="0.0" />
        <limit effort="100" lower="-0.524" upper="0.524" velocity="100" />
        <mimic joint="qbhand1_synergy_joint" multiplier="-0.2" />
    </joint>
    <transmission name="qbhand1_transmission">
        <type>transmission_interface/qbMoveTransmission</type>
        <joint name="qbhand1_index_knuckle_joint">
            <hardwareInterface>hardware_interface/EffortJointInterface</hardwareInterface>
        </joint>
        <actuator name="qbhand1_index_knuckle_joint">
            <hardwareInterface>hardware_interface/EffortJointInterface</hardwareInterface>
        </actuator>
    </transmission>
    <gazebo reference="qbhand1_index_knuckle_joint">
        <!-- TODO: add other Gazebo Joint properties (http://sdformat.org/spec?elem=joint) -->
    </gazebo>
    <link name="qbhand1_index_knuckle_link">
        <inertial>
            <mass value="0.0095" />
            <origin rpy="0 0 0" xyz="4.2753603e-04  0.0 -1.4321738e-03" />
            <inertia ixx="6.4337303e-07" ixy="0.0" ixz="-3.9373913e-08" iyy="1.1253771e-06" iyz="0.0" izz="7.2336948e-07" />
        </inertial>
        <visual>
            <origin rpy="0 0 0" xyz="0 0 0" />
            <geometry>
                <mesh filename="package://qb_hand_description/meshes/ph_knuckle.stl" scale="0.001 0.001 0.001" />
            </geometry>
            <material name="qbhand/knuckle" />
        </visual>
        <collision>
            <origin rpy="0 0 0" xyz="0 0 0" />
            <geometry>
                <mesh filename="package://qb_hand_description/meshes/ph_knuckle_collision.stl" scale="0.001 0.001 0.001" />
            </geometry>
        </collision>
    </link>
    <gazebo reference="qbhand1_index_knuckle_link">
        <self_collide>1</self_collide>
        <!-- TODO: add other Gazebo Link properties (http://sdformat.org/spec?elem=link) -->
        <!--      <collision>-->
        <!--        <surface>-->
        <!--          <contact>-->
        <!--            <ode>-->
        <!--              <kp>1.0</kp>-->
        <!--              <kd>0.01</kd>-->
        <!--              <max_vel>0.0</max_vel>-->
        <!--              <min_depth>0.001</min_depth>-->
        <!--            </ode>-->
        <!--          </contact>-->
        <!--          <friction>-->
        <!--            <ode>-->
        <!--              <mu>0.9</mu>-->
        <!--              <mu2>0.9</mu2>-->
        <!--            </ode>-->
        <!--          </friction>-->
        <!--        </surface>-->
        <!--      </collision>-->
    </gazebo>
    <joint name="qbhand1_index_proximal_joint" type="revolute">
        <origin rpy="1.57 0 0" xyz="0.009 0 0" />
        <parent link="qbhand1_index_knuckle_link" />
        <child link="qbhand1_index_proximal_virtual_link" />
        <axis xyz="0 0 -1" />
        <dynamics damping="0.0" friction="0.0" />
        <limit effort="100" lower="0.0" upper="0.785" velocity="100" />
        <mimic joint="qbhand1_synergy_joint" multiplier="0.785" />
    </joint>
    <transmission name="qbhand1_transmission">
        <type>transmission_interface/qbMoveTransmission</type>
        <joint name="qbhand1_index_proximal_joint">
            <hardwareInterface>hardware_interface/EffortJointInterface</hardwareInterface>
        </joint>
        <actuator name="qbhand1_index_proximal_joint">
            <hardwareInterface>hardware_interface/EffortJointInterface</hardwareInterface>
        </actuator>
    </transmission>
    <gazebo reference="qbhand1_index_proximal_joint">
        <!-- TODO: add other Gazebo Joint properties (http://sdformat.org/spec?elem=joint) -->
    </gazebo>
    <link name="qbhand1_index_proximal_virtual_link">
        <inertial>
            <origin rpy="0 0 0" xyz="0 0 0" />
            <mass value="1e-4" />
            <inertia ixx="1e-9" ixy="0.0" ixz="0.0" iyy="1e-9" iyz="0.0" izz="1e-9" />
        </inertial>
    </link>
    <joint name="qbhand1_index_proximal_virtual_joint" type="revolute">
        <origin rpy="0 0 0" xyz="0.013 0 0" />
        <parent link="qbhand1_index_proximal_virtual_link" />
        <child link="qbhand1_index_proximal_link" />
        <axis xyz="0 0 -1" />
        <dynamics damping="0.0" friction="0.0" />
        <limit effort="100" lower="0.0" upper="0.785" velocity="100" />
        <mimic joint="qbhand1_index_proximal_joint" multiplier="1.0" />
    </joint>
    <transmission name="qbhand1_transmission">
        <type>transmission_interface/qbMoveTransmission</type>
        <joint name="qbhand1_index_proximal_virtual_joint">
            <hardwareInterface>hardware_interface/EffortJointInterface</hardwareInterface>
        </joint>
        <actuator name="qbhand1_index_proximal_virtual_joint">
            <hardwareInterface>hardware_interface/EffortJointInterface</hardwareInterface>
        </actuator>
    </transmission>
    <gazebo reference="qbhand1_index_proximal_virtual_joint">
        <!-- TODO: add other Gazebo Joint properties (http://sdformat.org/spec?elem=joint) -->
    </gazebo>
    <link name="qbhand1_index_proximal_link">
        <inertial>
            <mass value="0.0082" />
            <origin rpy="0 0 0" xyz="8.7707437e-03 -1.7863138e-03 0.0" />
            <inertia ixx="2.2722068e-07" ixy="1.1586053e-08" ixz="0.0" iyy="5.5947233e-07" iyz="0.0" izz="5.9562195e-07" />
        </inertial>
        <visual>
            <origin rpy="0 0 0" xyz="0 0 0" />
            <geometry>
                <mesh filename="package://qb_hand_description/meshes/ph_medium.stl" scale="0.001 0.001 0.001" />
            </geometry>
            <material name="qbhand/proximal" />
        </visual>
        <collision>
            <origin rpy="0 0 0" xyz="0 0 0" />
            <geometry>
                <mesh filename="package://qb_hand_description/meshes/ph_medium_collision.stl" scale="0.001 0.001 0.001" />
            </geometry>
        </collision>
    </link>
    <gazebo reference="qbhand1_index_proximal_link">
        <self_collide>1</self_collide>
        <!-- TODO: add other Gazebo Link properties (http://sdformat.org/spec?elem=link) -->
        <!--      <collision>-->
        <!--        <surface>-->
        <!--          <contact>-->
        <!--            <ode>-->
        <!--              <kp>1.0</kp>-->
        <!--              <kd>0.01</kd>-->
        <!--              <max_vel>0.0</max_vel>-->
        <!--              <min_depth>0.001</min_depth>-->
        <!--            </ode>-->
        <!--          </contact>-->
        <!--          <friction>-->
        <!--            <ode>-->
        <!--              <mu>0.9</mu>-->
        <!--              <mu2>0.9</mu2>-->
        <!--            </ode>-->
        <!--          </friction>-->
        <!--        </surface>-->
        <!--      </collision>-->
    </gazebo>
    <joint name="qbhand1_index_middle_joint" type="revolute">
        <origin rpy="0 0 0" xyz="0.017 0 0" />
        <parent link="qbhand1_index_proximal_link" />
        <child link="qbhand1_index_middle_virtual_link" />
        <axis xyz="0 0 -1" />
        <dynamics damping="0.0" friction="0.0" />
        <limit effort="100" lower="0.0" upper="0.785" velocity="100" />
        <mimic joint="qbhand1_synergy_joint" multiplier="0.785" />
    </joint>
    <transmission name="qbhand1_transmission">
        <type>transmission_interface/qbMoveTransmission</type>
        <joint name="qbhand1_index_middle_joint">
            <hardwareInterface>hardware_interface/EffortJointInterface</hardwareInterface>
        </joint>
        <actuator name="qbhand1_index_middle_joint">
            <hardwareInterface>hardware_interface/EffortJointInterface</hardwareInterface>
        </actuator>
    </transmission>
    <gazebo reference="qbhand1_index_middle_joint">
        <!-- TODO: add other Gazebo Joint properties (http://sdformat.org/spec?elem=joint) -->
    </gazebo>
    <link name="qbhand1_index_middle_virtual_link">
        <inertial>
            <origin rpy="0 0 0" xyz="0 0 0" />
            <mass value="1e-4" />
            <inertia ixx="1e-9" ixy="0.0" ixz="0.0" iyy="1e-9" iyz="0.0" izz="1e-9" />
        </inertial>
    </link>
    <joint name="qbhand1_index_middle_virtual_joint" type="revolute">
        <origin rpy="0 0 0" xyz="0.013 0 0" />
        <parent link="qbhand1_index_middle_virtual_link" />
        <child link="qbhand1_index_middle_link" />
        <axis xyz="0 0 -1" />
        <dynamics damping="0.0" friction="0.0" />
        <limit effort="100" lower="0.0" upper="0.785" velocity="100" />
        <mimic joint="qbhand1_index_middle_joint" multiplier="1.0" />
    </joint>
    <transmission name="qbhand1_transmission">
        <type>transmission_interface/qbMoveTransmission</type>
        <joint name="qbhand1_index_middle_virtual_joint">
            <hardwareInterface>hardware_interface/EffortJointInterface</hardwareInterface>
        </joint>
        <actuator name="qbhand1_index_middle_virtual_joint">
            <hardwareInterface>hardware_interface/EffortJointInterface</hardwareInterface>
        </actuator>
    </transmission>
    <gazebo reference="qbhand1_index_middle_virtual_joint">
        <!-- TODO: add other Gazebo Joint properties (http://sdformat.org/spec?elem=joint) -->
    </gazebo>
    <link name="qbhand1_index_middle_link">
        <inertial>
            <mass value="0.0063" />
            <origin rpy="0 0 0" xyz="4.7601567e-03 -1.3786947e-03 0.0" />
            <inertia ixx="1.8024201e-07" ixy="5.756798e-09" ixz="0.0" iyy="2.3516266e-07" iyz="0.0" izz="2.691504e-07" />
        </inertial>
        <visual>
            <origin rpy="0 0 0" xyz="0 0 0" />
            <geometry>
                <mesh filename="package://qb_hand_description/meshes/ph_short.stl" scale="0.001 0.001 0.001" />
            </geometry>
            <material name="qbhand/middle" />
        </visual>
        <collision>
            <origin rpy="0 0 0" xyz="0 0 0" />
            <geometry>
                <mesh filename="package://qb_hand_description/meshes/ph_short_collision.stl" scale="0.001 0.001 0.001" />
            </geometry>
        </collision>
    </link>
    <gazebo reference="qbhand1_index_middle_link">
        <self_collide>1</self_collide>
        <!-- TODO: add other Gazebo Link properties (http://sdformat.org/spec?elem=link) -->
        <!--      <collision>-->
        <!--        <surface>-->
        <!--          <contact>-->
        <!--            <ode>-->
        <!--              <kp>1.0</kp>-->
        <!--              <kd>0.01</kd>-->
        <!--              <max_vel>0.0</max_vel>-->
        <!--              <min_depth>0.001</min_depth>-->
        <!--            </ode>-->
        <!--          </contact>-->
        <!--          <friction>-->
        <!--            <ode>-->
        <!--              <mu>0.9</mu>-->
        <!--              <mu2>0.9</mu2>-->
        <!--            </ode>-->
        <!--          </friction>-->
        <!--        </surface>-->
        <!--      </collision>-->
    </gazebo>
    <joint name="qbhand1_index_distal_joint" type="revolute">
        <origin rpy="0 0 0" xyz="0.009 0 0" />
        <parent link="qbhand1_index_middle_link" />
        <child link="qbhand1_index_distal_virtual_link" />
        <axis xyz="0 0 -1" />
        <dynamics damping="0.0" friction="0.0" />
        <limit effort="100" lower="0.0" upper="0.785" velocity="100" />
        <mimic joint="qbhand1_synergy_joint" multiplier="0.785" />
    </joint>
    <transmission name="qbhand1_transmission">
        <type>transmission_interface/qbMoveTransmission</type>
        <joint name="qbhand1_index_distal_joint">
            <hardwareInterface>hardware_interface/EffortJointInterface</hardwareInterface>
        </joint>
        <actuator name="qbhand1_index_distal_joint">
            <hardwareInterface>hardware_interface/EffortJointInterface</hardwareInterface>
        </actuator>
    </transmission>
    <gazebo reference="qbhand1_index_distal_joint">
        <!-- TODO: add other Gazebo Joint properties (http://sdformat.org/spec?elem=joint) -->
    </gazebo>
    <link name="qbhand1_index_distal_virtual_link">
        <inertial>
            <origin rpy="0 0 0" xyz="0 0 0" />
            <mass value="1e-4" />
            <inertia ixx="1e-9" ixy="0.0" ixz="0.0" iyy="1e-9" iyz="0.0" izz="1e-9" />
        </inertial>
    </link>
    <joint name="qbhand1_index_distal_virtual_joint" type="revolute">
        <origin rpy="0 0 0" xyz="0.013 0 0" />
        <parent link="qbhand1_index_distal_virtual_link" />
        <child link="qbhand1_index_distal_link" />
        <axis xyz="0 0 -1" />
        <dynamics damping="0.0" friction="0.0" />
        <limit effort="100" lower="0.0" upper="0.785" velocity="100" />
        <mimic joint="qbhand1_index_distal_joint" multiplier="1.0" />
    </joint>
    <transmission name="qbhand1_transmission">
        <type>transmission_interface/qbMoveTransmission</type>
        <joint name="qbhand1_index_distal_virtual_joint">
            <hardwareInterface>hardware_interface/EffortJointInterface</hardwareInterface>
        </joint>
        <actuator name="qbhand1_index_distal_virtual_joint">
            <hardwareInterface>hardware_interface/EffortJointInterface</hardwareInterface>
        </actuator>
    </transmission>
    <gazebo reference="qbhand1_index_distal_virtual_joint">
        <!-- TODO: add other Gazebo Joint properties (http://sdformat.org/spec?elem=joint) -->
    </gazebo>
    <link name="qbhand1_index_distal_link">
        <inertial>
            <mass value="0.009" />
            <origin rpy="0 0 0" xyz="8.8025467e-03 -1.7219289e-03 0.0" />
            <inertia ixx="2.6586142e-07" ixy="1.2416847e-08" ixz="0.0" iyy="5.9935767e-07" iyz="0.0" izz="6.6781963e-07" />
        </inertial>
        <visual>
            <origin rpy="0 0 0" xyz="0 0 0" />
            <geometry>
                <mesh filename="package://qb_hand_description/meshes/ph_distal.stl" scale="0.001 0.001 0.001" />
            </geometry>
            <material name="qbhand/distal" />
        </visual>
        <collision>
            <origin rpy="0 0 0" xyz="0 0 0" />
            <geometry>
                <mesh filename="package://qb_hand_description/meshes/ph_distal_collision.stl" scale="0.001 0.001 0.001" />
            </geometry>
        </collision>
    </link>
    <gazebo reference="qbhand1_index_distal_link">
        <self_collide>1</self_collide>
        <!-- TODO: add other Gazebo Link properties (http://sdformat.org/spec?elem=link) -->
        <!--      <collision>-->
        <!--        <surface>-->
        <!--          <contact>-->
        <!--            <ode>-->
        <!--              <kp>1.0</kp>-->
        <!--              <kd>0.01</kd>-->
        <!--              <max_vel>0.0</max_vel>-->
        <!--              <min_depth>0.001</min_depth>-->
        <!--            </ode>-->
        <!--          </contact>-->
        <!--          <friction>-->
        <!--            <ode>-->
        <!--              <mu>0.9</mu>-->
        <!--              <mu2>0.9</mu2>-->
        <!--            </ode>-->
        <!--          </friction>-->
        <!--        </surface>-->
        <!--      </collision>-->
    </gazebo>
    <joint name="qbhand1_middle_knuckle_joint" type="revolute">
        <origin rpy="0 0 1.57" xyz="0 0 0.014" />
        <parent link="qbhand1_palm_link" />
        <child link="qbhand1_middle_knuckle_link" />
        <axis xyz="0 0 -1" />
        <dynamics damping="0.0" friction="0.0" />
        <limit effort="100" lower="-0.524" upper="0.524" velocity="100" />
        <mimic joint="qbhand1_synergy_joint" multiplier="0.0" />
    </joint>
    <transmission name="qbhand1_transmission">
        <type>transmission_interface/qbMoveTransmission</type>
        <joint name="qbhand1_middle_knuckle_joint">
            <hardwareInterface>hardware_interface/EffortJointInterface</hardwareInterface>
        </joint>
        <actuator name="qbhand1_middle_knuckle_joint">
            <hardwareInterface>hardware_interface/EffortJointInterface</hardwareInterface>
        </actuator>
    </transmission>
    <gazebo reference="qbhand1_middle_knuckle_joint">
        <!-- TODO: add other Gazebo Joint properties (http://sdformat.org/spec?elem=joint) -->
    </gazebo>
    <link name="qbhand1_middle_knuckle_link">
        <inertial>
            <mass value="0.0095" />
            <origin rpy="0 0 0" xyz="4.2753603e-04  0.0 -1.4321738e-03" />
            <inertia ixx="6.4337303e-07" ixy="0.0" ixz="-3.9373913e-08" iyy="1.1253771e-06" iyz="0.0" izz="7.2336948e-07" />
        </inertial>
        <visual>
            <origin rpy="0 0 0" xyz="0 0 0" />
            <geometry>
                <mesh filename="package://qb_hand_description/meshes/ph_knuckle.stl" scale="0.001 0.001 0.001" />
            </geometry>
            <material name="qbhand/knuckle" />
        </visual>
        <collision>
            <origin rpy="0 0 0" xyz="0 0 0" />
            <geometry>
                <mesh filename="package://qb_hand_description/meshes/ph_knuckle_collision.stl" scale="0.001 0.001 0.001" />
            </geometry>
        </collision>
    </link>
    <gazebo reference="qbhand1_middle_knuckle_link">
        <self_collide>1</self_collide>
        <!-- TODO: add other Gazebo Link properties (http://sdformat.org/spec?elem=link) -->
        <!--      <collision>-->
        <!--        <surface>-->
        <!--          <contact>-->
        <!--            <ode>-->
        <!--              <kp>1.0</kp>-->
        <!--              <kd>0.01</kd>-->
        <!--              <max_vel>0.0</max_vel>-->
        <!--              <min_depth>0.001</min_depth>-->
        <!--            </ode>-->
        <!--          </contact>-->
        <!--          <friction>-->
        <!--            <ode>-->
        <!--              <mu>0.9</mu>-->
        <!--              <mu2>0.9</mu2>-->
        <!--            </ode>-->
        <!--          </friction>-->
        <!--        </surface>-->
        <!--      </collision>-->
    </gazebo>
    <joint name="qbhand1_middle_proximal_joint" type="revolute">
        <origin rpy="1.57 0 0" xyz="0.009 0 0" />
        <parent link="qbhand1_middle_knuckle_link" />
        <child link="qbhand1_middle_proximal_virtual_link" />
        <axis xyz="0 0 -1" />
        <dynamics damping="0.0" friction="0.0" />
        <limit effort="100" lower="0.0" upper="0.785" velocity="100" />
        <mimic joint="qbhand1_synergy_joint" multiplier="0.785" />
    </joint>
    <transmission name="qbhand1_transmission">
        <type>transmission_interface/qbMoveTransmission</type>
        <joint name="qbhand1_middle_proximal_joint">
            <hardwareInterface>hardware_interface/EffortJointInterface</hardwareInterface>
        </joint>
        <actuator name="qbhand1_middle_proximal_joint">
            <hardwareInterface>hardware_interface/EffortJointInterface</hardwareInterface>
        </actuator>
    </transmission>
    <gazebo reference="qbhand1_middle_proximal_joint">
        <!-- TODO: add other Gazebo Joint properties (http://sdformat.org/spec?elem=joint) -->
    </gazebo>
    <link name="qbhand1_middle_proximal_virtual_link">
        <inertial>
            <origin rpy="0 0 0" xyz="0 0 0" />
            <mass value="1e-4" />
            <inertia ixx="1e-9" ixy="0.0" ixz="0.0" iyy="1e-9" iyz="0.0" izz="1e-9" />
        </inertial>
    </link>
    <joint name="qbhand1_middle_proximal_virtual_joint" type="revolute">
        <origin rpy="0 0 0" xyz="0.013 0 0" />
        <parent link="qbhand1_middle_proximal_virtual_link" />
        <child link="qbhand1_middle_proximal_link" />
        <axis xyz="0 0 -1" />
        <dynamics damping="0.0" friction="0.0" />
        <limit effort="100" lower="0.0" upper="0.785" velocity="100" />
        <mimic joint="qbhand1_middle_proximal_joint" multiplier="1.0" />
    </joint>
    <transmission name="qbhand1_transmission">
        <type>transmission_interface/qbMoveTransmission</type>
        <joint name="qbhand1_middle_proximal_virtual_joint">
            <hardwareInterface>hardware_interface/EffortJointInterface</hardwareInterface>
        </joint>
        <actuator name="qbhand1_middle_proximal_virtual_joint">
            <hardwareInterface>hardware_interface/EffortJointInterface</hardwareInterface>
        </actuator>
    </transmission>
    <gazebo reference="qbhand1_middle_proximal_virtual_joint">
        <!-- TODO: add other Gazebo Joint properties (http://sdformat.org/spec?elem=joint) -->
    </gazebo>
    <link name="qbhand1_middle_proximal_link">
        <inertial>
            <mass value="0.0082" />
            <origin rpy="0 0 0" xyz="8.7707437e-03 -1.7863138e-03 0.0" />
            <inertia ixx="2.2722068e-07" ixy="1.1586053e-08" ixz="0.0" iyy="5.5947233e-07" iyz="0.0" izz="5.9562195e-07" />
        </inertial>
        <visual>
            <origin rpy="0 0 0" xyz="0 0 0" />
            <geometry>
                <mesh filename="package://qb_hand_description/meshes/ph_medium.stl" scale="0.001 0.001 0.001" />
            </geometry>
            <material name="qbhand/proximal" />
        </visual>
        <collision>
            <origin rpy="0 0 0" xyz="0 0 0" />
            <geometry>
                <mesh filename="package://qb_hand_description/meshes/ph_medium_collision.stl" scale="0.001 0.001 0.001" />
            </geometry>
        </collision>
    </link>
    <gazebo reference="qbhand1_middle_proximal_link">
        <self_collide>1</self_collide>
        <!-- TODO: add other Gazebo Link properties (http://sdformat.org/spec?elem=link) -->
        <!--      <collision>-->
        <!--        <surface>-->
        <!--          <contact>-->
        <!--            <ode>-->
        <!--              <kp>1.0</kp>-->
        <!--              <kd>0.01</kd>-->
        <!--              <max_vel>0.0</max_vel>-->
        <!--              <min_depth>0.001</min_depth>-->
        <!--            </ode>-->
        <!--          </contact>-->
        <!--          <friction>-->
        <!--            <ode>-->
        <!--              <mu>0.9</mu>-->
        <!--              <mu2>0.9</mu2>-->
        <!--            </ode>-->
        <!--          </friction>-->
        <!--        </surface>-->
        <!--      </collision>-->
    </gazebo>
    <joint name="qbhand1_middle_middle_joint" type="revolute">
        <origin rpy="0 0 0" xyz="0.017 0 0" />
        <parent link="qbhand1_middle_proximal_link" />
        <child link="qbhand1_middle_middle_virtual_link" />
        <axis xyz="0 0 -1" />
        <dynamics damping="0.0" friction="0.0" />
        <limit effort="100" lower="0.0" upper="0.785" velocity="100" />
        <mimic joint="qbhand1_synergy_joint" multiplier="0.785" />
    </joint>
    <transmission name="qbhand1_transmission">
        <type>transmission_interface/qbMoveTransmission</type>
        <joint name="qbhand1_middle_middle_joint">
            <hardwareInterface>hardware_interface/EffortJointInterface</hardwareInterface>
        </joint>
        <actuator name="qbhand1_middle_middle_joint">
            <hardwareInterface>hardware_interface/EffortJointInterface</hardwareInterface>
        </actuator>
    </transmission>
    <gazebo reference="qbhand1_middle_middle_joint">
        <!-- TODO: add other Gazebo Joint properties (http://sdformat.org/spec?elem=joint) -->
    </gazebo>
    <link name="qbhand1_middle_middle_virtual_link">
        <inertial>
            <origin rpy="0 0 0" xyz="0 0 0" />
            <mass value="1e-4" />
            <inertia ixx="1e-9" ixy="0.0" ixz="0.0" iyy="1e-9" iyz="0.0" izz="1e-9" />
        </inertial>
    </link>
    <joint name="qbhand1_middle_middle_virtual_joint" type="revolute">
        <origin rpy="0 0 0" xyz="0.013 0 0" />
        <parent link="qbhand1_middle_middle_virtual_link" />
        <child link="qbhand1_middle_middle_link" />
        <axis xyz="0 0 -1" />
        <dynamics damping="0.0" friction="0.0" />
        <limit effort="100" lower="0.0" upper="0.785" velocity="100" />
        <mimic joint="qbhand1_middle_middle_joint" multiplier="1.0" />
    </joint>
    <transmission name="qbhand1_transmission">
        <type>transmission_interface/qbMoveTransmission</type>
        <joint name="qbhand1_middle_middle_virtual_joint">
            <hardwareInterface>hardware_interface/EffortJointInterface</hardwareInterface>
        </joint>
        <actuator name="qbhand1_middle_middle_virtual_joint">
            <hardwareInterface>hardware_interface/EffortJointInterface</hardwareInterface>
        </actuator>
    </transmission>
    <gazebo reference="qbhand1_middle_middle_virtual_joint">
        <!-- TODO: add other Gazebo Joint properties (http://sdformat.org/spec?elem=joint) -->
    </gazebo>
    <link name="qbhand1_middle_middle_link">
        <inertial>
            <mass value="0.0063" />
            <origin rpy="0 0 0" xyz="4.7601567e-03 -1.3786947e-03 0.0" />
            <inertia ixx="1.8024201e-07" ixy="5.756798e-09" ixz="0.0" iyy="2.3516266e-07" iyz="0.0" izz="2.691504e-07" />
        </inertial>
        <visual>
            <origin rpy="0 0 0" xyz="0 0 0" />
            <geometry>
                <mesh filename="package://qb_hand_description/meshes/ph_short.stl" scale="0.001 0.001 0.001" />
            </geometry>
            <material name="qbhand/middle" />
        </visual>
        <collision>
            <origin rpy="0 0 0" xyz="0 0 0" />
            <geometry>
                <mesh filename="package://qb_hand_description/meshes/ph_short_collision.stl" scale="0.001 0.001 0.001" />
            </geometry>
        </collision>
    </link>
    <gazebo reference="qbhand1_middle_middle_link">
        <self_collide>1</self_collide>
        <!-- TODO: add other Gazebo Link properties (http://sdformat.org/spec?elem=link) -->
        <!--      <collision>-->
        <!--        <surface>-->
        <!--          <contact>-->
        <!--            <ode>-->
        <!--              <kp>1.0</kp>-->
        <!--              <kd>0.01</kd>-->
        <!--              <max_vel>0.0</max_vel>-->
        <!--              <min_depth>0.001</min_depth>-->
        <!--            </ode>-->
        <!--          </contact>-->
        <!--          <friction>-->
        <!--            <ode>-->
        <!--              <mu>0.9</mu>-->
        <!--              <mu2>0.9</mu2>-->
        <!--            </ode>-->
        <!--          </friction>-->
        <!--        </surface>-->
        <!--      </collision>-->
    </gazebo>
    <joint name="qbhand1_middle_distal_joint" type="revolute">
        <origin rpy="0 0 0" xyz="0.009 0 0" />
        <parent link="qbhand1_middle_middle_link" />
        <child link="qbhand1_middle_distal_virtual_link" />
        <axis xyz="0 0 -1" />
        <dynamics damping="0.0" friction="0.0" />
        <limit effort="100" lower="0.0" upper="0.785" velocity="100" />
        <mimic joint="qbhand1_synergy_joint" multiplier="0.785" />
    </joint>
    <transmission name="qbhand1_transmission">
        <type>transmission_interface/qbMoveTransmission</type>
        <joint name="qbhand1_middle_distal_joint">
            <hardwareInterface>hardware_interface/EffortJointInterface</hardwareInterface>
        </joint>
        <actuator name="qbhand1_middle_distal_joint">
            <hardwareInterface>hardware_interface/EffortJointInterface</hardwareInterface>
        </actuator>
    </transmission>
    <gazebo reference="qbhand1_middle_distal_joint">
        <!-- TODO: add other Gazebo Joint properties (http://sdformat.org/spec?elem=joint) -->
    </gazebo>
    <link name="qbhand1_middle_distal_virtual_link">
        <inertial>
            <origin rpy="0 0 0" xyz="0 0 0" />
            <mass value="1e-4" />
            <inertia ixx="1e-9" ixy="0.0" ixz="0.0" iyy="1e-9" iyz="0.0" izz="1e-9" />
        </inertial>
    </link>
    <joint name="qbhand1_middle_distal_virtual_joint" type="revolute">
        <origin rpy="0 0 0" xyz="0.013 0 0" />
        <parent link="qbhand1_middle_distal_virtual_link" />
        <child link="qbhand1_middle_distal_link" />
        <axis xyz="0 0 -1" />
        <dynamics damping="0.0" friction="0.0" />
        <limit effort="100" lower="0.0" upper="0.785" velocity="100" />
        <mimic joint="qbhand1_middle_distal_joint" multiplier="1.0" />
    </joint>
    <transmission name="qbhand1_transmission">
        <type>transmission_interface/qbMoveTransmission</type>
        <joint name="qbhand1_middle_distal_virtual_joint">
            <hardwareInterface>hardware_interface/EffortJointInterface</hardwareInterface>
        </joint>
        <actuator name="qbhand1_middle_distal_virtual_joint">
            <hardwareInterface>hardware_interface/EffortJointInterface</hardwareInterface>
        </actuator>
    </transmission>
    <gazebo reference="qbhand1_middle_distal_virtual_joint">
        <!-- TODO: add other Gazebo Joint properties (http://sdformat.org/spec?elem=joint) -->
    </gazebo>
    <link name="qbhand1_middle_distal_link">
        <inertial>
            <mass value="0.009" />
            <origin rpy="0 0 0" xyz="8.8025467e-03 -1.7219289e-03 0.0" />
            <inertia ixx="2.6586142e-07" ixy="1.2416847e-08" ixz="0.0" iyy="5.9935767e-07" iyz="0.0" izz="6.6781963e-07" />
        </inertial>
        <visual>
            <origin rpy="0 0 0" xyz="0 0 0" />
            <geometry>
                <mesh filename="package://qb_hand_description/meshes/ph_distal.stl" scale="0.001 0.001 0.001" />
            </geometry>
            <material name="qbhand/distal" />
        </visual>
        <collision>
            <origin rpy="0 0 0" xyz="0 0 0" />
            <geometry>
                <mesh filename="package://qb_hand_description/meshes/ph_distal_collision.stl" scale="0.001 0.001 0.001" />
            </geometry>
        </collision>
    </link>
    <gazebo reference="qbhand1_middle_distal_link">
        <self_collide>1</self_collide>
        <!-- TODO: add other Gazebo Link properties (http://sdformat.org/spec?elem=link) -->
        <!--      <collision>-->
        <!--        <surface>-->
        <!--          <contact>-->
        <!--            <ode>-->
        <!--              <kp>1.0</kp>-->
        <!--              <kd>0.01</kd>-->
        <!--              <max_vel>0.0</max_vel>-->
        <!--              <min_depth>0.001</min_depth>-->
        <!--            </ode>-->
        <!--          </contact>-->
        <!--          <friction>-->
        <!--            <ode>-->
        <!--              <mu>0.9</mu>-->
        <!--              <mu2>0.9</mu2>-->
        <!--            </ode>-->
        <!--          </friction>-->
        <!--        </surface>-->
        <!--      </collision>-->
    </gazebo>
    <joint name="qbhand1_ring_knuckle_joint" type="revolute">
        <origin rpy="0 0 1.57" xyz="0.02 -0.007 0.014" />
        <parent link="qbhand1_palm_link" />
        <child link="qbhand1_ring_knuckle_link" />
        <axis xyz="0 0 -1" />
        <dynamics damping="0.0" friction="0.0" />
        <limit effort="100" lower="-0.524" upper="0.524" velocity="100" />
        <mimic joint="qbhand1_synergy_joint" multiplier="0.2" />
    </joint>
    <transmission name="qbhand1_transmission">
        <type>transmission_interface/qbMoveTransmission</type>
        <joint name="qbhand1_ring_knuckle_joint">
            <hardwareInterface>hardware_interface/EffortJointInterface</hardwareInterface>
        </joint>
        <actuator name="qbhand1_ring_knuckle_joint">
            <hardwareInterface>hardware_interface/EffortJointInterface</hardwareInterface>
        </actuator>
    </transmission>
    <gazebo reference="qbhand1_ring_knuckle_joint">
        <!-- TODO: add other Gazebo Joint properties (http://sdformat.org/spec?elem=joint) -->
    </gazebo>
    <link name="qbhand1_ring_knuckle_link">
        <inertial>
            <mass value="0.0095" />
            <origin rpy="0 0 0" xyz="4.2753603e-04  0.0 -1.4321738e-03" />
            <inertia ixx="6.4337303e-07" ixy="0.0" ixz="-3.9373913e-08" iyy="1.1253771e-06" iyz="0.0" izz="7.2336948e-07" />
        </inertial>
        <visual>
            <origin rpy="0 0 0" xyz="0 0 0" />
            <geometry>
                <mesh filename="package://qb_hand_description/meshes/ph_knuckle.stl" scale="0.001 0.001 0.001" />
            </geometry>
            <material name="qbhand/knuckle" />
        </visual>
        <collision>
            <origin rpy="0 0 0" xyz="0 0 0" />
            <geometry>
                <mesh filename="package://qb_hand_description/meshes/ph_knuckle_collision.stl" scale="0.001 0.001 0.001" />
            </geometry>
        </collision>
    </link>
    <gazebo reference="qbhand1_ring_knuckle_link">
        <self_collide>1</self_collide>
        <!-- TODO: add other Gazebo Link properties (http://sdformat.org/spec?elem=link) -->
        <!--      <collision>-->
        <!--        <surface>-->
        <!--          <contact>-->
        <!--            <ode>-->
        <!--              <kp>1.0</kp>-->
        <!--              <kd>0.01</kd>-->
        <!--              <max_vel>0.0</max_vel>-->
        <!--              <min_depth>0.001</min_depth>-->
        <!--            </ode>-->
        <!--          </contact>-->
        <!--          <friction>-->
        <!--            <ode>-->
        <!--              <mu>0.9</mu>-->
        <!--              <mu2>0.9</mu2>-->
        <!--            </ode>-->
        <!--          </friction>-->
        <!--        </surface>-->
        <!--      </collision>-->
    </gazebo>
    <joint name="qbhand1_ring_proximal_joint" type="revolute">
        <origin rpy="1.57 0 0" xyz="0.009 0 0" />
        <parent link="qbhand1_ring_knuckle_link" />
        <child link="qbhand1_ring_proximal_virtual_link" />
        <axis xyz="0 0 -1" />
        <dynamics damping="0.0" friction="0.0" />
        <limit effort="100" lower="0.0" upper="0.785" velocity="100" />
        <mimic joint="qbhand1_synergy_joint" multiplier="0.785" />
    </joint>
    <transmission name="qbhand1_transmission">
        <type>transmission_interface/qbMoveTransmission</type>
        <joint name="qbhand1_ring_proximal_joint">
            <hardwareInterface>hardware_interface/EffortJointInterface</hardwareInterface>
        </joint>
        <actuator name="qbhand1_ring_proximal_joint">
            <hardwareInterface>hardware_interface/EffortJointInterface</hardwareInterface>
        </actuator>
    </transmission>
    <gazebo reference="qbhand1_ring_proximal_joint">
        <!-- TODO: add other Gazebo Joint properties (http://sdformat.org/spec?elem=joint) -->
    </gazebo>
    <link name="qbhand1_ring_proximal_virtual_link">
        <inertial>
            <origin rpy="0 0 0" xyz="0 0 0" />
            <mass value="1e-4" />
            <inertia ixx="1e-9" ixy="0.0" ixz="0.0" iyy="1e-9" iyz="0.0" izz="1e-9" />
        </inertial>
    </link>
    <joint name="qbhand1_ring_proximal_virtual_joint" type="revolute">
        <origin rpy="0 0 0" xyz="0.013 0 0" />
        <parent link="qbhand1_ring_proximal_virtual_link" />
        <child link="qbhand1_ring_proximal_link" />
        <axis xyz="0 0 -1" />
        <dynamics damping="0.0" friction="0.0" />
        <limit effort="100" lower="0.0" upper="0.785" velocity="100" />
        <mimic joint="qbhand1_ring_proximal_joint" multiplier="1.0" />
    </joint>
    <transmission name="qbhand1_transmission">
        <type>transmission_interface/qbMoveTransmission</type>
        <joint name="qbhand1_ring_proximal_virtual_joint">
            <hardwareInterface>hardware_interface/EffortJointInterface</hardwareInterface>
        </joint>
        <actuator name="qbhand1_ring_proximal_virtual_joint">
            <hardwareInterface>hardware_interface/EffortJointInterface</hardwareInterface>
        </actuator>
    </transmission>
    <gazebo reference="qbhand1_ring_proximal_virtual_joint">
        <!-- TODO: add other Gazebo Joint properties (http://sdformat.org/spec?elem=joint) -->
    </gazebo>
    <link name="qbhand1_ring_proximal_link">
        <inertial>
            <mass value="0.0082" />
            <origin rpy="0 0 0" xyz="8.7707437e-03 -1.7863138e-03 0.0" />
            <inertia ixx="2.2722068e-07" ixy="1.1586053e-08" ixz="0.0" iyy="5.5947233e-07" iyz="0.0" izz="5.9562195e-07" />
        </inertial>
        <visual>
            <origin rpy="0 0 0" xyz="0 0 0" />
            <geometry>
                <mesh filename="package://qb_hand_description/meshes/ph_medium.stl" scale="0.001 0.001 0.001" />
            </geometry>
            <material name="qbhand/proximal" />
        </visual>
        <collision>
            <origin rpy="0 0 0" xyz="0 0 0" />
            <geometry>
                <mesh filename="package://qb_hand_description/meshes/ph_medium_collision.stl" scale="0.001 0.001 0.001" />
            </geometry>
        </collision>
    </link>
    <gazebo reference="qbhand1_ring_proximal_link">
        <self_collide>1</self_collide>
        <!-- TODO: add other Gazebo Link properties (http://sdformat.org/spec?elem=link) -->
        <!--      <collision>-->
        <!--        <surface>-->
        <!--          <contact>-->
        <!--            <ode>-->
        <!--              <kp>1.0</kp>-->
        <!--              <kd>0.01</kd>-->
        <!--              <max_vel>0.0</max_vel>-->
        <!--              <min_depth>0.001</min_depth>-->
        <!--            </ode>-->
        <!--          </contact>-->
        <!--          <friction>-->
        <!--            <ode>-->
        <!--              <mu>0.9</mu>-->
        <!--              <mu2>0.9</mu2>-->
        <!--            </ode>-->
        <!--          </friction>-->
        <!--        </surface>-->
        <!--      </collision>-->
    </gazebo>
    <joint name="qbhand1_ring_middle_joint" type="revolute">
        <origin rpy="0 0 0" xyz="0.017 0 0" />
        <parent link="qbhand1_ring_proximal_link" />
        <child link="qbhand1_ring_middle_virtual_link" />
        <axis xyz="0 0 -1" />
        <dynamics damping="0.0" friction="0.0" />
        <limit effort="100" lower="0.0" upper="0.785" velocity="100" />
        <mimic joint="qbhand1_synergy_joint" multiplier="0.785" />
    </joint>
    <transmission name="qbhand1_transmission">
        <type>transmission_interface/qbMoveTransmission</type>
        <joint name="qbhand1_ring_middle_joint">
            <hardwareInterface>hardware_interface/EffortJointInterface</hardwareInterface>
        </joint>
        <actuator name="qbhand1_ring_middle_joint">
            <hardwareInterface>hardware_interface/EffortJointInterface</hardwareInterface>
        </actuator>
    </transmission>
    <gazebo reference="qbhand1_ring_middle_joint">
        <!-- TODO: add other Gazebo Joint properties (http://sdformat.org/spec?elem=joint) -->
    </gazebo>
    <link name="qbhand1_ring_middle_virtual_link">
        <inertial>
            <origin rpy="0 0 0" xyz="0 0 0" />
            <mass value="1e-4" />
            <inertia ixx="1e-9" ixy="0.0" ixz="0.0" iyy="1e-9" iyz="0.0" izz="1e-9" />
        </inertial>
    </link>
    <joint name="qbhand1_ring_middle_virtual_joint" type="revolute">
        <origin rpy="0 0 0" xyz="0.013 0 0" />
        <parent link="qbhand1_ring_middle_virtual_link" />
        <child link="qbhand1_ring_middle_link" />
        <axis xyz="0 0 -1" />
        <dynamics damping="0.0" friction="0.0" />
        <limit effort="100" lower="0.0" upper="0.785" velocity="100" />
        <mimic joint="qbhand1_ring_middle_joint" multiplier="1.0" />
    </joint>
    <transmission name="qbhand1_transmission">
        <type>transmission_interface/qbMoveTransmission</type>
        <joint name="qbhand1_ring_middle_virtual_joint">
            <hardwareInterface>hardware_interface/EffortJointInterface</hardwareInterface>
        </joint>
        <actuator name="qbhand1_ring_middle_virtual_joint">
            <hardwareInterface>hardware_interface/EffortJointInterface</hardwareInterface>
        </actuator>
    </transmission>
    <gazebo reference="qbhand1_ring_middle_virtual_joint">
        <!-- TODO: add other Gazebo Joint properties (http://sdformat.org/spec?elem=joint) -->
    </gazebo>
    <link name="qbhand1_ring_middle_link">
        <inertial>
            <mass value="0.0063" />
            <origin rpy="0 0 0" xyz="4.7601567e-03 -1.3786947e-03 0.0" />
            <inertia ixx="1.8024201e-07" ixy="5.756798e-09" ixz="0.0" iyy="2.3516266e-07" iyz="0.0" izz="2.691504e-07" />
        </inertial>
        <visual>
            <origin rpy="0 0 0" xyz="0 0 0" />
            <geometry>
                <mesh filename="package://qb_hand_description/meshes/ph_short.stl" scale="0.001 0.001 0.001" />
            </geometry>
            <material name="qbhand/middle" />
        </visual>
        <collision>
            <origin rpy="0 0 0" xyz="0 0 0" />
            <geometry>
                <mesh filename="package://qb_hand_description/meshes/ph_short_collision.stl" scale="0.001 0.001 0.001" />
            </geometry>
        </collision>
    </link>
    <gazebo reference="qbhand1_ring_middle_link">
        <self_collide>1</self_collide>
        <!-- TODO: add other Gazebo Link properties (http://sdformat.org/spec?elem=link) -->
        <!--      <collision>-->
        <!--        <surface>-->
        <!--          <contact>-->
        <!--            <ode>-->
        <!--              <kp>1.0</kp>-->
        <!--              <kd>0.01</kd>-->
        <!--              <max_vel>0.0</max_vel>-->
        <!--              <min_depth>0.001</min_depth>-->
        <!--            </ode>-->
        <!--          </contact>-->
        <!--          <friction>-->
        <!--            <ode>-->
        <!--              <mu>0.9</mu>-->
        <!--              <mu2>0.9</mu2>-->
        <!--            </ode>-->
        <!--          </friction>-->
        <!--        </surface>-->
        <!--      </collision>-->
    </gazebo>
    <joint name="qbhand1_ring_distal_joint" type="revolute">
        <origin rpy="0 0 0" xyz="0.009 0 0" />
        <parent link="qbhand1_ring_middle_link" />
        <child link="qbhand1_ring_distal_virtual_link" />
        <axis xyz="0 0 -1" />
        <dynamics damping="0.0" friction="0.0" />
        <limit effort="100" lower="0.0" upper="0.785" velocity="100" />
        <mimic joint="qbhand1_synergy_joint" multiplier="0.785" />
    </joint>
    <transmission name="qbhand1_transmission">
        <type>transmission_interface/qbMoveTransmission</type>
        <joint name="qbhand1_ring_distal_joint">
            <hardwareInterface>hardware_interface/EffortJointInterface</hardwareInterface>
        </joint>
        <actuator name="qbhand1_ring_distal_joint">
            <hardwareInterface>hardware_interface/EffortJointInterface</hardwareInterface>
        </actuator>
    </transmission>
    <gazebo reference="qbhand1_ring_distal_joint">
        <!-- TODO: add other Gazebo Joint properties (http://sdformat.org/spec?elem=joint) -->
    </gazebo>
    <link name="qbhand1_ring_distal_virtual_link">
        <inertial>
            <origin rpy="0 0 0" xyz="0 0 0" />
            <mass value="1e-4" />
            <inertia ixx="1e-9" ixy="0.0" ixz="0.0" iyy="1e-9" iyz="0.0" izz="1e-9" />
        </inertial>
    </link>
    <joint name="qbhand1_ring_distal_virtual_joint" type="revolute">
        <origin rpy="0 0 0" xyz="0.013 0 0" />
        <parent link="qbhand1_ring_distal_virtual_link" />
        <child link="qbhand1_ring_distal_link" />
        <axis xyz="0 0 -1" />
        <dynamics damping="0.0" friction="0.0" />
        <limit effort="100" lower="0.0" upper="0.785" velocity="100" />
        <mimic joint="qbhand1_ring_distal_joint" multiplier="1.0" />
    </joint>
    <transmission name="qbhand1_transmission">
        <type>transmission_interface/qbMoveTransmission</type>
        <joint name="qbhand1_ring_distal_virtual_joint">
            <hardwareInterface>hardware_interface/EffortJointInterface</hardwareInterface>
        </joint>
        <actuator name="qbhand1_ring_distal_virtual_joint">
            <hardwareInterface>hardware_interface/EffortJointInterface</hardwareInterface>
        </actuator>
    </transmission>
    <gazebo reference="qbhand1_ring_distal_virtual_joint">
        <!-- TODO: add other Gazebo Joint properties (http://sdformat.org/spec?elem=joint) -->
    </gazebo>
    <link name="qbhand1_ring_distal_link">
        <inertial>
            <mass value="0.009" />
            <origin rpy="0 0 0" xyz="8.8025467e-03 -1.7219289e-03 0.0" />
            <inertia ixx="2.6586142e-07" ixy="1.2416847e-08" ixz="0.0" iyy="5.9935767e-07" iyz="0.0" izz="6.6781963e-07" />
        </inertial>
        <visual>
            <origin rpy="0 0 0" xyz="0 0 0" />
            <geometry>
                <mesh filename="package://qb_hand_description/meshes/ph_distal.stl" scale="0.001 0.001 0.001" />
            </geometry>
            <material name="qbhand/distal" />
        </visual>
        <collision>
            <origin rpy="0 0 0" xyz="0 0 0" />
            <geometry>
                <mesh filename="package://qb_hand_description/meshes/ph_distal_collision.stl" scale="0.001 0.001 0.001" />
            </geometry>
        </collision>
    </link>
    <gazebo reference="qbhand1_ring_distal_link">
        <self_collide>1</self_collide>
        <!-- TODO: add other Gazebo Link properties (http://sdformat.org/spec?elem=link) -->
        <!--      <collision>-->
        <!--        <surface>-->
        <!--          <contact>-->
        <!--            <ode>-->
        <!--              <kp>1.0</kp>-->
        <!--              <kd>0.01</kd>-->
        <!--              <max_vel>0.0</max_vel>-->
        <!--              <min_depth>0.001</min_depth>-->
        <!--            </ode>-->
        <!--          </contact>-->
        <!--          <friction>-->
        <!--            <ode>-->
        <!--              <mu>0.9</mu>-->
        <!--              <mu2>0.9</mu2>-->
        <!--            </ode>-->
        <!--          </friction>-->
        <!--        </surface>-->
        <!--      </collision>-->
    </gazebo>
    <joint name="qbhand1_little_knuckle_joint" type="revolute">
        <origin rpy="0 0 1.57" xyz="0.04 -0.012 0.014" />
        <parent link="qbhand1_palm_link" />
        <child link="qbhand1_little_knuckle_link" />
        <axis xyz="0 0 -1" />
        <dynamics damping="0.0" friction="0.0" />
        <limit effort="100" lower="-0.524" upper="0.524" velocity="100" />
        <mimic joint="qbhand1_synergy_joint" multiplier="0.4" />
    </joint>
    <transmission name="qbhand1_transmission">
        <type>transmission_interface/qbMoveTransmission</type>
        <joint name="qbhand1_little_knuckle_joint">
            <hardwareInterface>hardware_interface/EffortJointInterface</hardwareInterface>
        </joint>
        <actuator name="qbhand1_little_knuckle_joint">
            <hardwareInterface>hardware_interface/EffortJointInterface</hardwareInterface>
        </actuator>
    </transmission>
    <gazebo reference="qbhand1_little_knuckle_joint">
        <!-- TODO: add other Gazebo Joint properties (http://sdformat.org/spec?elem=joint) -->
    </gazebo>
    <link name="qbhand1_little_knuckle_link">
        <inertial>
            <mass value="0.0095" />
            <origin rpy="0 0 0" xyz="4.2753603e-04  0.0 -1.4321738e-03" />
            <inertia ixx="6.4337303e-07" ixy="0.0" ixz="-3.9373913e-08" iyy="1.1253771e-06" iyz="0.0" izz="7.2336948e-07" />
        </inertial>
        <visual>
            <origin rpy="0 0 0" xyz="0 0 0" />
            <geometry>
                <mesh filename="package://qb_hand_description/meshes/ph_knuckle.stl" scale="0.001 0.001 0.001" />
            </geometry>
            <material name="qbhand/knuckle" />
        </visual>
        <collision>
            <origin rpy="0 0 0" xyz="0 0 0" />
            <geometry>
                <mesh filename="package://qb_hand_description/meshes/ph_knuckle_collision.stl" scale="0.001 0.001 0.001" />
            </geometry>
        </collision>
    </link>
    <gazebo reference="qbhand1_little_knuckle_link">
        <self_collide>1</self_collide>
        <!-- TODO: add other Gazebo Link properties (http://sdformat.org/spec?elem=link) -->
        <!--      <collision>-->
        <!--        <surface>-->
        <!--          <contact>-->
        <!--            <ode>-->
        <!--              <kp>1.0</kp>-->
        <!--              <kd>0.01</kd>-->
        <!--              <max_vel>0.0</max_vel>-->
        <!--              <min_depth>0.001</min_depth>-->
        <!--            </ode>-->
        <!--          </contact>-->
        <!--          <friction>-->
        <!--            <ode>-->
        <!--              <mu>0.9</mu>-->
        <!--              <mu2>0.9</mu2>-->
        <!--            </ode>-->
        <!--          </friction>-->
        <!--        </surface>-->
        <!--      </collision>-->
    </gazebo>
    <joint name="qbhand1_little_proximal_joint" type="revolute">
        <origin rpy="1.57 0 0" xyz="0.009 0 0" />
        <parent link="qbhand1_little_knuckle_link" />
        <child link="qbhand1_little_proximal_virtual_link" />
        <axis xyz="0 0 -1" />
        <dynamics damping="0.0" friction="0.0" />
        <limit effort="100" lower="0.0" upper="0.785" velocity="100" />
        <mimic joint="qbhand1_synergy_joint" multiplier="0.785" />
    </joint>
    <transmission name="qbhand1_transmission">
        <type>transmission_interface/qbMoveTransmission</type>
        <joint name="qbhand1_little_proximal_joint">
            <hardwareInterface>hardware_interface/EffortJointInterface</hardwareInterface>
        </joint>
        <actuator name="qbhand1_little_proximal_joint">
            <hardwareInterface>hardware_interface/EffortJointInterface</hardwareInterface>
        </actuator>
    </transmission>
    <gazebo reference="qbhand1_little_proximal_joint">
        <!-- TODO: add other Gazebo Joint properties (http://sdformat.org/spec?elem=joint) -->
    </gazebo>
    <link name="qbhand1_little_proximal_virtual_link">
        <inertial>
            <origin rpy="0 0 0" xyz="0 0 0" />
            <mass value="1e-4" />
            <inertia ixx="1e-9" ixy="0.0" ixz="0.0" iyy="1e-9" iyz="0.0" izz="1e-9" />
        </inertial>
    </link>
    <joint name="qbhand1_little_proximal_virtual_joint" type="revolute">
        <origin rpy="0 0 0" xyz="0.013 0 0" />
        <parent link="qbhand1_little_proximal_virtual_link" />
        <child link="qbhand1_little_proximal_link" />
        <axis xyz="0 0 -1" />
        <dynamics damping="0.0" friction="0.0" />
        <limit effort="100" lower="0.0" upper="0.785" velocity="100" />
        <mimic joint="qbhand1_little_proximal_joint" multiplier="1.0" />
    </joint>
    <transmission name="qbhand1_transmission">
        <type>transmission_interface/qbMoveTransmission</type>
        <joint name="qbhand1_little_proximal_virtual_joint">
            <hardwareInterface>hardware_interface/EffortJointInterface</hardwareInterface>
        </joint>
        <actuator name="qbhand1_little_proximal_virtual_joint">
            <hardwareInterface>hardware_interface/EffortJointInterface</hardwareInterface>
        </actuator>
    </transmission>
    <gazebo reference="qbhand1_little_proximal_virtual_joint">
        <!-- TODO: add other Gazebo Joint properties (http://sdformat.org/spec?elem=joint) -->
    </gazebo>
    <link name="qbhand1_little_proximal_link">
        <inertial>
            <mass value="0.0063" />
            <origin rpy="0 0 0" xyz="4.7601567e-03 -1.3786947e-03 0.0" />
            <inertia ixx="1.8024201e-07" ixy="5.756798e-09" ixz="0.0" iyy="2.3516266e-07" iyz="0.0" izz="2.691504e-07" />
        </inertial>
        <visual>
            <origin rpy="0 0 0" xyz="0 0 0" />
            <geometry>
                <mesh filename="package://qb_hand_description/meshes/ph_short.stl" scale="0.001 0.001 0.001" />
            </geometry>
            <material name="qbhand/proximal" />
        </visual>
        <collision>
            <origin rpy="0 0 0" xyz="0 0 0" />
            <geometry>
                <mesh filename="package://qb_hand_description/meshes/ph_short_collision.stl" scale="0.001 0.001 0.001" />
            </geometry>
        </collision>
    </link>
    <gazebo reference="qbhand1_little_proximal_link">
        <self_collide>1</self_collide>
        <!-- TODO: add other Gazebo Link properties (http://sdformat.org/spec?elem=link) -->
        <!--      <collision>-->
        <!--        <surface>-->
        <!--          <contact>-->
        <!--            <ode>-->
        <!--              <kp>1.0</kp>-->
        <!--              <kd>0.01</kd>-->
        <!--              <max_vel>0.0</max_vel>-->
        <!--              <min_depth>0.001</min_depth>-->
        <!--            </ode>-->
        <!--          </contact>-->
        <!--          <friction>-->
        <!--            <ode>-->
        <!--              <mu>0.9</mu>-->
        <!--              <mu2>0.9</mu2>-->
        <!--            </ode>-->
        <!--          </friction>-->
        <!--        </surface>-->
        <!--      </collision>-->
    </gazebo>
    <joint name="qbhand1_little_middle_joint" type="revolute">
        <origin rpy="0 0 0" xyz="0.009 0 0" />
        <parent link="qbhand1_little_proximal_link" />
        <child link="qbhand1_little_middle_virtual_link" />
        <axis xyz="0 0 -1" />
        <dynamics damping="0.0" friction="0.0" />
        <limit effort="100" lower="0.0" upper="0.785" velocity="100" />
        <mimic joint="qbhand1_synergy_joint" multiplier="0.785" />
    </joint>
    <transmission name="qbhand1_transmission">
        <type>transmission_interface/qbMoveTransmission</type>
        <joint name="qbhand1_little_middle_joint">
            <hardwareInterface>hardware_interface/EffortJointInterface</hardwareInterface>
        </joint>
        <actuator name="qbhand1_little_middle_joint">
            <hardwareInterface>hardware_interface/EffortJointInterface</hardwareInterface>
        </actuator>
    </transmission>
    <gazebo reference="qbhand1_little_middle_joint">
        <!-- TODO: add other Gazebo Joint properties (http://sdformat.org/spec?elem=joint) -->
    </gazebo>
    <link name="qbhand1_little_middle_virtual_link">
        <inertial>
            <origin rpy="0 0 0" xyz="0 0 0" />
            <mass value="1e-4" />
            <inertia ixx="1e-9" ixy="0.0" ixz="0.0" iyy="1e-9" iyz="0.0" izz="1e-9" />
        </inertial>
    </link>
    <joint name="qbhand1_little_middle_virtual_joint" type="revolute">
        <origin rpy="0 0 0" xyz="0.013 0 0" />
        <parent link="qbhand1_little_middle_virtual_link" />
        <child link="qbhand1_little_middle_link" />
        <axis xyz="0 0 -1" />
        <dynamics damping="0.0" friction="0.0" />
        <limit effort="100" lower="0.0" upper="0.785" velocity="100" />
        <mimic joint="qbhand1_little_middle_joint" multiplier="1.0" />
    </joint>
    <transmission name="qbhand1_transmission">
        <type>transmission_interface/qbMoveTransmission</type>
        <joint name="qbhand1_little_middle_virtual_joint">
            <hardwareInterface>hardware_interface/EffortJointInterface</hardwareInterface>
        </joint>
        <actuator name="qbhand1_little_middle_virtual_joint">
            <hardwareInterface>hardware_interface/EffortJointInterface</hardwareInterface>
        </actuator>
    </transmission>
    <gazebo reference="qbhand1_little_middle_virtual_joint">
        <!-- TODO: add other Gazebo Joint properties (http://sdformat.org/spec?elem=joint) -->
    </gazebo>
    <link name="qbhand1_little_middle_link">
        <inertial>
            <mass value="0.0063" />
            <origin rpy="0 0 0" xyz="4.7601567e-03 -1.3786947e-03 0.0" />
            <inertia ixx="1.8024201e-07" ixy="5.756798e-09" ixz="0.0" iyy="2.3516266e-07" iyz="0.0" izz="2.691504e-07" />
        </inertial>
        <visual>
            <origin rpy="0 0 0" xyz="0 0 0" />
            <geometry>
                <mesh filename="package://qb_hand_description/meshes/ph_short.stl" scale="0.001 0.001 0.001" />
            </geometry>
            <material name="qbhand/middle" />
        </visual>
        <collision>
            <origin rpy="0 0 0" xyz="0 0 0" />
            <geometry>
                <mesh filename="package://qb_hand_description/meshes/ph_short_collision.stl" scale="0.001 0.001 0.001" />
            </geometry>
        </collision>
    </link>
    <gazebo reference="qbhand1_little_middle_link">
        <self_collide>1</self_collide>
        <!-- TODO: add other Gazebo Link properties (http://sdformat.org/spec?elem=link) -->
        <!--      <collision>-->
        <!--        <surface>-->
        <!--          <contact>-->
        <!--            <ode>-->
        <!--              <kp>1.0</kp>-->
        <!--              <kd>0.01</kd>-->
        <!--              <max_vel>0.0</max_vel>-->
        <!--              <min_depth>0.001</min_depth>-->
        <!--            </ode>-->
        <!--          </contact>-->
        <!--          <friction>-->
        <!--            <ode>-->
        <!--              <mu>0.9</mu>-->
        <!--              <mu2>0.9</mu2>-->
        <!--            </ode>-->
        <!--          </friction>-->
        <!--        </surface>-->
        <!--      </collision>-->
    </gazebo>
    <joint name="qbhand1_little_distal_joint" type="revolute">
        <origin rpy="0 0 0" xyz="0.009 0 0" />
        <parent link="qbhand1_little_middle_link" />
        <child link="qbhand1_little_distal_virtual_link" />
        <axis xyz="0 0 -1" />
        <dynamics damping="0.0" friction="0.0" />
        <limit effort="100" lower="0.0" upper="0.785" velocity="100" />
        <mimic joint="qbhand1_synergy_joint" multiplier="0.785" />
    </joint>
    <transmission name="qbhand1_transmission">
        <type>transmission_interface/qbMoveTransmission</type>
        <joint name="qbhand1_little_distal_joint">
            <hardwareInterface>hardware_interface/EffortJointInterface</hardwareInterface>
        </joint>
        <actuator name="qbhand1_little_distal_joint">
            <hardwareInterface>hardware_interface/EffortJointInterface</hardwareInterface>
        </actuator>
    </transmission>
    <gazebo reference="qbhand1_little_distal_joint">
        <!-- TODO: add other Gazebo Joint properties (http://sdformat.org/spec?elem=joint) -->
    </gazebo>
    <link name="qbhand1_little_distal_virtual_link">
        <inertial>
            <origin rpy="0 0 0" xyz="0 0 0" />
            <mass value="1e-4" />
            <inertia ixx="1e-9" ixy="0.0" ixz="0.0" iyy="1e-9" iyz="0.0" izz="1e-9" />
        </inertial>
    </link>
    <joint name="qbhand1_little_distal_virtual_joint" type="revolute">
        <origin rpy="0 0 0" xyz="0.013 0 0" />
        <parent link="qbhand1_little_distal_virtual_link" />
        <child link="qbhand1_little_distal_link" />
        <axis xyz="0 0 -1" />
        <dynamics damping="0.0" friction="0.0" />
        <limit effort="100" lower="0.0" upper="0.785" velocity="100" />
        <mimic joint="qbhand1_little_distal_joint" multiplier="1.0" />
    </joint>
    <transmission name="qbhand1_transmission">
        <type>transmission_interface/qbMoveTransmission</type>
        <joint name="qbhand1_little_distal_virtual_joint">
            <hardwareInterface>hardware_interface/EffortJointInterface</hardwareInterface>
        </joint>
        <actuator name="qbhand1_little_distal_virtual_joint">
            <hardwareInterface>hardware_interface/EffortJointInterface</hardwareInterface>
        </actuator>
    </transmission>
    <gazebo reference="qbhand1_little_distal_virtual_joint">
        <!-- TODO: add other Gazebo Joint properties (http://sdformat.org/spec?elem=joint) -->
    </gazebo>
    <link name="qbhand1_little_distal_link">
        <inertial>
            <mass value="0.009" />
            <origin rpy="0 0 0" xyz="8.8025467e-03 -1.7219289e-03 0.0" />
            <inertia ixx="2.6586142e-07" ixy="1.2416847e-08" ixz="0.0" iyy="5.9935767e-07" iyz="0.0" izz="6.6781963e-07" />
        </inertial>
        <visual>
            <origin rpy="0 0 0" xyz="0 0 0" />
            <geometry>
                <mesh filename="package://qb_hand_description/meshes/ph_distal.stl" scale="0.001 0.001 0.001" />
            </geometry>
            <material name="qbhand/distal" />
        </visual>
        <collision>
            <origin rpy="0 0 0" xyz="0 0 0" />
            <geometry>
                <mesh filename="package://qb_hand_description/meshes/ph_distal_collision.stl" scale="0.001 0.001 0.001" />
            </geometry>
        </collision>
    </link>
    <gazebo reference="qbhand1_little_distal_link">
        <self_collide>1</self_collide>
        <!-- TODO: add other Gazebo Link properties (http://sdformat.org/spec?elem=link) -->
        <!--      <collision>-->
        <!--        <surface>-->
        <!--          <contact>-->
        <!--            <ode>-->
        <!--              <kp>1.0</kp>-->
        <!--              <kd>0.01</kd>-->
        <!--              <max_vel>0.0</max_vel>-->
        <!--              <min_depth>0.001</min_depth>-->
        <!--            </ode>-->
        <!--          </contact>-->
        <!--          <friction>-->
        <!--            <ode>-->
        <!--              <mu>0.9</mu>-->
        <!--              <mu2>0.9</mu2>-->
        <!--            </ode>-->
        <!--          </friction>-->
        <!--        </surface>-->
        <!--      </collision>-->
    </gazebo>
    <!-- EXTRA ENDEFFECTOR Classical one -->
    <joint name="right_hand_ee_joint" type="fixed">
        <origin rpy="0 0 0" xyz="0.13 -0.003 0.037" />
        <parent link="panda_link8" />
        <child link="right_hand_ee_link" />
    </joint>
    <link name="right_hand_ee_link" />
    <!-- Thumb index ee link frame -->
    <link name="thumb_index_ee_link" />
    <joint name="thumb_index_ee_joint" type="fixed">
        <origin rpy="0 0.5 -1.0" xyz="0.07 -0.04 0.03" />
        <parent link="right_hand_ee_link" />
        <child link="thumb_index_ee_link" />
    </joint>
    <transmission name="trans_panda_joint1">
        <type>transmission_interface/SimpleTransmission</type>
        <joint name="panda_joint1">
            <hardwareInterface>hardware_interface/PositionJointInterface</hardwareInterface>
        </joint>
        <actuator name="panda_joint1_motor">
            <hardwareInterface>hardware_interface/PositionJointInterface</hardwareInterface>
            <mechanicalReduction>1</mechanicalReduction>
        </actuator>
    </transmission>
    <transmission name="trans_panda_joint2">
        <type>transmission_interface/SimpleTransmission</type>
        <joint name="panda_joint2">
            <hardwareInterface>hardware_interface/PositionJointInterface</hardwareInterface>
        </joint>
        <actuator name="panda_joint2_motor">
            <hardwareInterface>hardware_interface/PositionJointInterface</hardwareInterface>
            <mechanicalReduction>1</mechanicalReduction>
        </actuator>
    </transmission>
    <transmission name="trans_panda_joint3">
        <type>transmission_interface/SimpleTransmission</type>
        <joint name="panda_joint3">
            <hardwareInterface>hardware_interface/PositionJointInterface</hardwareInterface>
        </joint>
        <actuator name="panda_joint3_motor">
            <hardwareInterface>hardware_interface/PositionJointInterface</hardwareInterface>
            <mechanicalReduction>1</mechanicalReduction>
        </actuator>
    </transmission>
    <transmission name="trans_panda_joint4">
        <type>transmission_interface/SimpleTransmission</type>
        <joint name="panda_joint4">
            <hardwareInterface>hardware_interface/PositionJointInterface</hardwareInterface>
        </joint>
        <actuator name="panda_joint4_motor">
            <hardwareInterface>hardware_interface/PositionJointInterface</hardwareInterface>
            <mechanicalReduction>1</mechanicalReduction>
        </actuator>
    </transmission>
    <transmission name="trans_panda_joint5">
        <type>transmission_interface/SimpleTransmission</type>
        <joint name="panda_joint5">
            <hardwareInterface>hardware_interface/PositionJointInterface</hardwareInterface>
        </joint>
        <actuator name="panda_joint5_motor">
            <hardwareInterface>hardware_interface/PositionJointInterface</hardwareInterface>
            <mechanicalReduction>1</mechanicalReduction>
        </actuator>
    </transmission>
    <transmission name="trans_panda_joint6">
        <type>transmission_interface/SimpleTransmission</type>
        <joint name="panda_joint6">
            <hardwareInterface>hardware_interface/PositionJointInterface</hardwareInterface>
        </joint>
        <actuator name="panda_joint6_motor">
            <hardwareInterface>hardware_interface/PositionJointInterface</hardwareInterface>
            <mechanicalReduction>1</mechanicalReduction>
        </actuator>
    </transmission>
    <transmission name="trans_panda_joint7">
        <type>transmission_interface/SimpleTransmission</type>
        <joint name="panda_joint7">
            <hardwareInterface>hardware_interface/PositionJointInterface</hardwareInterface>
        </joint>
        <actuator name="panda_joint7_motor">
            <hardwareInterface>hardware_interface/PositionJointInterface</hardwareInterface>
            <mechanicalReduction>1</mechanicalReduction>
        </actuator>
    </transmission>
    <transmission name="trans_qbhand1_synergy_joint">
        <type>transmission_interface/SimpleTransmission</type>
        <joint name="qbhand1_synergy_joint">
            <hardwareInterface>hardware_interface/EffortJointInterface</hardwareInterface>
        </joint>
        <actuator name="qbhand1_synergy_joint_motor">
            <hardwareInterface>hardware_interface/EffortJointInterface</hardwareInterface>
            <mechanicalReduction>1</mechanicalReduction>
        </actuator>
    </transmission>
    <transmission name="trans_qbhand1_thumb_knuckle_joint">
        <type>transmission_interface/SimpleTransmission</type>
        <joint name="qbhand1_thumb_knuckle_joint">
            <hardwareInterface>hardware_interface/EffortJointInterface</hardwareInterface>
        </joint>
        <actuator name="qbhand1_thumb_knuckle_joint_motor">
            <hardwareInterface>hardware_interface/EffortJointInterface</hardwareInterface>
            <mechanicalReduction>1</mechanicalReduction>
        </actuator>
    </transmission>
    <transmission name="trans_qbhand1_thumb_proximal_joint">
        <type>transmission_interface/SimpleTransmission</type>
        <joint name="qbhand1_thumb_proximal_joint">
            <hardwareInterface>hardware_interface/EffortJointInterface</hardwareInterface>
        </joint>
        <actuator name="qbhand1_thumb_proximal_joint_motor">
            <hardwareInterface>hardware_interface/EffortJointInterface</hardwareInterface>
            <mechanicalReduction>1</mechanicalReduction>
        </actuator>
    </transmission>
    <transmission name="trans_qbhand1_thumb_proximal_virtual_joint">
        <type>transmission_interface/SimpleTransmission</type>
        <joint name="qbhand1_thumb_proximal_virtual_joint">
            <hardwareInterface>hardware_interface/EffortJointInterface</hardwareInterface>
        </joint>
        <actuator name="qbhand1_thumb_proximal_virtual_joint_motor">
            <hardwareInterface>hardware_interface/EffortJointInterface</hardwareInterface>
            <mechanicalReduction>1</mechanicalReduction>
        </actuator>
    </transmission>
    <transmission name="trans_qbhand1_thumb_distal_joint">
        <type>transmission_interface/SimpleTransmission</type>
        <joint name="qbhand1_thumb_distal_joint">
            <hardwareInterface>hardware_interface/EffortJointInterface</hardwareInterface>
        </joint>
        <actuator name="qbhand1_thumb_distal_joint_motor">
            <hardwareInterface>hardware_interface/EffortJointInterface</hardwareInterface>
            <mechanicalReduction>1</mechanicalReduction>
        </actuator>
    </transmission>
    <transmission name="trans_qbhand1_thumb_distal_virtual_joint">
        <type>transmission_interface/SimpleTransmission</type>
        <joint name="qbhand1_thumb_distal_virtual_joint">
            <hardwareInterface>hardware_interface/EffortJointInterface</hardwareInterface>
        </joint>
        <actuator name="qbhand1_thumb_distal_virtual_joint_motor">
            <hardwareInterface>hardware_interface/EffortJointInterface</hardwareInterface>
            <mechanicalReduction>1</mechanicalReduction>
        </actuator>
    </transmission>
    <transmission name="trans_qbhand1_index_knuckle_joint">
        <type>transmission_interface/SimpleTransmission</type>
        <joint name="qbhand1_index_knuckle_joint">
            <hardwareInterface>hardware_interface/EffortJointInterface</hardwareInterface>
        </joint>
        <actuator name="qbhand1_index_knuckle_joint_motor">
            <hardwareInterface>hardware_interface/EffortJointInterface</hardwareInterface>
            <mechanicalReduction>1</mechanicalReduction>
        </actuator>
    </transmission>
    <transmission name="trans_qbhand1_index_proximal_joint">
        <type>transmission_interface/SimpleTransmission</type>
        <joint name="qbhand1_index_proximal_joint">
            <hardwareInterface>hardware_interface/EffortJointInterface</hardwareInterface>
        </joint>
        <actuator name="qbhand1_index_proximal_joint_motor">
            <hardwareInterface>hardware_interface/EffortJointInterface</hardwareInterface>
            <mechanicalReduction>1</mechanicalReduction>
        </actuator>
    </transmission>
    <transmission name="trans_qbhand1_index_proximal_virtual_joint">
        <type>transmission_interface/SimpleTransmission</type>
        <joint name="qbhand1_index_proximal_virtual_joint">
            <hardwareInterface>hardware_interface/EffortJointInterface</hardwareInterface>
        </joint>
        <actuator name="qbhand1_index_proximal_virtual_joint_motor">
            <hardwareInterface>hardware_interface/EffortJointInterface</hardwareInterface>
            <mechanicalReduction>1</mechanicalReduction>
        </actuator>
    </transmission>
    <transmission name="trans_qbhand1_index_middle_joint">
        <type>transmission_interface/SimpleTransmission</type>
        <joint name="qbhand1_index_middle_joint">
            <hardwareInterface>hardware_interface/EffortJointInterface</hardwareInterface>
        </joint>
        <actuator name="qbhand1_index_middle_joint_motor">
            <hardwareInterface>hardware_interface/EffortJointInterface</hardwareInterface>
            <mechanicalReduction>1</mechanicalReduction>
        </actuator>
    </transmission>
    <transmission name="trans_qbhand1_index_middle_virtual_joint">
        <type>transmission_interface/SimpleTransmission</type>
        <joint name="qbhand1_index_middle_virtual_joint">
            <hardwareInterface>hardware_interface/EffortJointInterface</hardwareInterface>
        </joint>
        <actuator name="qbhand1_index_middle_virtual_joint_motor">
            <hardwareInterface>hardware_interface/EffortJointInterface</hardwareInterface>
            <mechanicalReduction>1</mechanicalReduction>
        </actuator>
    </transmission>
    <transmission name="trans_qbhand1_index_distal_joint">
        <type>transmission_interface/SimpleTransmission</type>
        <joint name="qbhand1_index_distal_joint">
            <hardwareInterface>hardware_interface/EffortJointInterface</hardwareInterface>
        </joint>
        <actuator name="qbhand1_index_distal_joint_motor">
            <hardwareInterface>hardware_interface/EffortJointInterface</hardwareInterface>
            <mechanicalReduction>1</mechanicalReduction>
        </actuator>
    </transmission>
    <transmission name="trans_qbhand1_index_distal_virtual_joint">
        <type>transmission_interface/SimpleTransmission</type>
        <joint name="qbhand1_index_distal_virtual_joint">
            <hardwareInterface>hardware_interface/EffortJointInterface</hardwareInterface>
        </joint>
        <actuator name="qbhand1_index_distal_virtual_joint_motor">
            <hardwareInterface>hardware_interface/EffortJointInterface</hardwareInterface>
            <mechanicalReduction>1</mechanicalReduction>
        </actuator>
    </transmission>
    <transmission name="trans_qbhand1_middle_knuckle_joint">
        <type>transmission_interface/SimpleTransmission</type>
        <joint name="qbhand1_middle_knuckle_joint">
            <hardwareInterface>hardware_interface/EffortJointInterface</hardwareInterface>
        </joint>
        <actuator name="qbhand1_middle_knuckle_joint_motor">
            <hardwareInterface>hardware_interface/EffortJointInterface</hardwareInterface>
            <mechanicalReduction>1</mechanicalReduction>
        </actuator>
    </transmission>
    <transmission name="trans_qbhand1_middle_proximal_joint">
        <type>transmission_interface/SimpleTransmission</type>
        <joint name="qbhand1_middle_proximal_joint">
            <hardwareInterface>hardware_interface/EffortJointInterface</hardwareInterface>
        </joint>
        <actuator name="qbhand1_middle_proximal_joint_motor">
            <hardwareInterface>hardware_interface/EffortJointInterface</hardwareInterface>
            <mechanicalReduction>1</mechanicalReduction>
        </actuator>
    </transmission>
    <transmission name="trans_qbhand1_middle_proximal_virtual_joint">
        <type>transmission_interface/SimpleTransmission</type>
        <joint name="qbhand1_middle_proximal_virtual_joint">
            <hardwareInterface>hardware_interface/EffortJointInterface</hardwareInterface>
        </joint>
        <actuator name="qbhand1_middle_proximal_virtual_joint_motor">
            <hardwareInterface>hardware_interface/EffortJointInterface</hardwareInterface>
            <mechanicalReduction>1</mechanicalReduction>
        </actuator>
    </transmission>
    <transmission name="trans_qbhand1_middle_middle_joint">
        <type>transmission_interface/SimpleTransmission</type>
        <joint name="qbhand1_middle_middle_joint">
            <hardwareInterface>hardware_interface/EffortJointInterface</hardwareInterface>
        </joint>
        <actuator name="qbhand1_middle_middle_joint_motor">
            <hardwareInterface>hardware_interface/EffortJointInterface</hardwareInterface>
            <mechanicalReduction>1</mechanicalReduction>
        </actuator>
    </transmission>
    <transmission name="trans_qbhand1_middle_middle_virtual_joint">
        <type>transmission_interface/SimpleTransmission</type>
        <joint name="qbhand1_middle_middle_virtual_joint">
            <hardwareInterface>hardware_interface/EffortJointInterface</hardwareInterface>
        </joint>
        <actuator name="qbhand1_middle_middle_virtual_joint_motor">
            <hardwareInterface>hardware_interface/EffortJointInterface</hardwareInterface>
            <mechanicalReduction>1</mechanicalReduction>
        </actuator>
    </transmission>
    <transmission name="trans_qbhand1_middle_distal_joint">
        <type>transmission_interface/SimpleTransmission</type>
        <joint name="qbhand1_middle_distal_joint">
            <hardwareInterface>hardware_interface/EffortJointInterface</hardwareInterface>
        </joint>
        <actuator name="qbhand1_middle_distal_joint_motor">
            <hardwareInterface>hardware_interface/EffortJointInterface</hardwareInterface>
            <mechanicalReduction>1</mechanicalReduction>
        </actuator>
    </transmission>
    <transmission name="trans_qbhand1_middle_distal_virtual_joint">
        <type>transmission_interface/SimpleTransmission</type>
        <joint name="qbhand1_middle_distal_virtual_joint">
            <hardwareInterface>hardware_interface/EffortJointInterface</hardwareInterface>
        </joint>
        <actuator name="qbhand1_middle_distal_virtual_joint_motor">
            <hardwareInterface>hardware_interface/EffortJointInterface</hardwareInterface>
            <mechanicalReduction>1</mechanicalReduction>
        </actuator>
    </transmission>
    <transmission name="trans_qbhand1_ring_knuckle_joint">
        <type>transmission_interface/SimpleTransmission</type>
        <joint name="qbhand1_ring_knuckle_joint">
            <hardwareInterface>hardware_interface/EffortJointInterface</hardwareInterface>
        </joint>
        <actuator name="qbhand1_ring_knuckle_joint_motor">
            <hardwareInterface>hardware_interface/EffortJointInterface</hardwareInterface>
            <mechanicalReduction>1</mechanicalReduction>
        </actuator>
    </transmission>
    <transmission name="trans_qbhand1_ring_proximal_joint">
        <type>transmission_interface/SimpleTransmission</type>
        <joint name="qbhand1_ring_proximal_joint">
            <hardwareInterface>hardware_interface/EffortJointInterface</hardwareInterface>
        </joint>
        <actuator name="qbhand1_ring_proximal_joint_motor">
            <hardwareInterface>hardware_interface/EffortJointInterface</hardwareInterface>
            <mechanicalReduction>1</mechanicalReduction>
        </actuator>
    </transmission>
    <transmission name="trans_qbhand1_ring_proximal_virtual_joint">
        <type>transmission_interface/SimpleTransmission</type>
        <joint name="qbhand1_ring_proximal_virtual_joint">
            <hardwareInterface>hardware_interface/EffortJointInterface</hardwareInterface>
        </joint>
        <actuator name="qbhand1_ring_proximal_virtual_joint_motor">
            <hardwareInterface>hardware_interface/EffortJointInterface</hardwareInterface>
            <mechanicalReduction>1</mechanicalReduction>
        </actuator>
    </transmission>
    <transmission name="trans_qbhand1_ring_middle_joint">
        <type>transmission_interface/SimpleTransmission</type>
        <joint name="qbhand1_ring_middle_joint">
            <hardwareInterface>hardware_interface/EffortJointInterface</hardwareInterface>
        </joint>
        <actuator name="qbhand1_ring_middle_joint_motor">
            <hardwareInterface>hardware_interface/EffortJointInterface</hardwareInterface>
            <mechanicalReduction>1</mechanicalReduction>
        </actuator>
    </transmission>
    <transmission name="trans_qbhand1_ring_middle_virtual_joint">
        <type>transmission_interface/SimpleTransmission</type>
        <joint name="qbhand1_ring_middle_virtual_joint">
            <hardwareInterface>hardware_interface/EffortJointInterface</hardwareInterface>
        </joint>
        <actuator name="qbhand1_ring_middle_virtual_joint_motor">
            <hardwareInterface>hardware_interface/EffortJointInterface</hardwareInterface>
            <mechanicalReduction>1</mechanicalReduction>
        </actuator>
    </transmission>
    <transmission name="trans_qbhand1_ring_distal_joint">
        <type>transmission_interface/SimpleTransmission</type>
        <joint name="qbhand1_ring_distal_joint">
            <hardwareInterface>hardware_interface/EffortJointInterface</hardwareInterface>
        </joint>
        <actuator name="qbhand1_ring_distal_joint_motor">
            <hardwareInterface>hardware_interface/EffortJointInterface</hardwareInterface>
            <mechanicalReduction>1</mechanicalReduction>
        </actuator>
    </transmission>
    <transmission name="trans_qbhand1_ring_distal_virtual_joint">
        <type>transmission_interface/SimpleTransmission</type>
        <joint name="qbhand1_ring_distal_virtual_joint">
            <hardwareInterface>hardware_interface/EffortJointInterface</hardwareInterface>
        </joint>
        <actuator name="qbhand1_ring_distal_virtual_joint_motor">
            <hardwareInterface>hardware_interface/EffortJointInterface</hardwareInterface>
            <mechanicalReduction>1</mechanicalReduction>
        </actuator>
    </transmission>
    <transmission name="trans_qbhand1_little_knuckle_joint">
        <type>transmission_interface/SimpleTransmission</type>
        <joint name="qbhand1_little_knuckle_joint">
            <hardwareInterface>hardware_interface/EffortJointInterface</hardwareInterface>
        </joint>
        <actuator name="qbhand1_little_knuckle_joint_motor">
            <hardwareInterface>hardware_interface/EffortJointInterface</hardwareInterface>
            <mechanicalReduction>1</mechanicalReduction>
        </actuator>
    </transmission>
    <transmission name="trans_qbhand1_little_proximal_joint">
        <type>transmission_interface/SimpleTransmission</type>
        <joint name="qbhand1_little_proximal_joint">
            <hardwareInterface>hardware_interface/EffortJointInterface</hardwareInterface>
        </joint>
        <actuator name="qbhand1_little_proximal_joint_motor">
            <hardwareInterface>hardware_interface/EffortJointInterface</hardwareInterface>
            <mechanicalReduction>1</mechanicalReduction>
        </actuator>
    </transmission>
    <transmission name="trans_qbhand1_little_proximal_virtual_joint">
        <type>transmission_interface/SimpleTransmission</type>
        <joint name="qbhand1_little_proximal_virtual_joint">
            <hardwareInterface>hardware_interface/EffortJointInterface</hardwareInterface>
        </joint>
        <actuator name="qbhand1_little_proximal_virtual_joint_motor">
            <hardwareInterface>hardware_interface/EffortJointInterface</hardwareInterface>
            <mechanicalReduction>1</mechanicalReduction>
        </actuator>
    </transmission>
    <transmission name="trans_qbhand1_little_middle_joint">
        <type>transmission_interface/SimpleTransmission</type>
        <joint name="qbhand1_little_middle_joint">
            <hardwareInterface>hardware_interface/EffortJointInterface</hardwareInterface>
        </joint>
        <actuator name="qbhand1_little_middle_joint_motor">
            <hardwareInterface>hardware_interface/EffortJointInterface</hardwareInterface>
            <mechanicalReduction>1</mechanicalReduction>
        </actuator>
    </transmission>
    <transmission name="trans_qbhand1_little_middle_virtual_joint">
        <type>transmission_interface/SimpleTransmission</type>
        <joint name="qbhand1_little_middle_virtual_joint">
            <hardwareInterface>hardware_interface/EffortJointInterface</hardwareInterface>
        </joint>
        <actuator name="qbhand1_little_middle_virtual_joint_motor">
            <hardwareInterface>hardware_interface/EffortJointInterface</hardwareInterface>
            <mechanicalReduction>1</mechanicalReduction>
        </actuator>
    </transmission>
    <transmission name="trans_qbhand1_little_distal_joint">
        <type>transmission_interface/SimpleTransmission</type>
        <joint name="qbhand1_little_distal_joint">
            <hardwareInterface>hardware_interface/EffortJointInterface</hardwareInterface>
        </joint>
        <actuator name="qbhand1_little_distal_joint_motor">
            <hardwareInterface>hardware_interface/EffortJointInterface</hardwareInterface>
            <mechanicalReduction>1</mechanicalReduction>
        </actuator>
    </transmission>
    <transmission name="trans_qbhand1_little_distal_virtual_joint">
        <type>transmission_interface/SimpleTransmission</type>
        <joint name="qbhand1_little_distal_virtual_joint">
            <hardwareInterface>hardware_interface/EffortJointInterface</hardwareInterface>
        </joint>
        <actuator name="qbhand1_little_distal_virtual_joint_motor">
            <hardwareInterface>hardware_interface/EffortJointInterface</hardwareInterface>
            <mechanicalReduction>1</mechanicalReduction>
        </actuator>
    </transmission>
</robot>

